Workbook

Sheet Objectifs Sciences 2022-2023
A1: Objectifs d'apprentissage du tronc commun de la formation en sciences au sein de l'Ecole d'Ingénieurs CESI
A2: A - Fondamentaux en sciences physiques (notions de prérequis) | B2: 1 | C2: Cycle préparatoire (CPI)
A3: A.1 Connaître les grandes notions de mécanique, d'électricité, de thermodynamique
A4: A.2 Mobiliser les 3 compétences élémentaires dans des exercices d'application (Modéliser, Calculer, Raisonner)
A5: B - Calcul numérique et analytique
A6: B.1 Faire preuve d'autonomie, d'initiative dans la démarche de résolution d'un problème
A7: B.2 Savoir employer une démarche de résolution analytico-numérique (du modèle physique ou des hypothèses jusqu'à l'implémentation)
A8: B.3 Savoir lire, comprendre, concevoir des algorithmes (sans langage spécifique, en privilégiant le pseudo-code)
A9: B.4 Savoir analyser et interpréter un résultat, avoir un point de vue critique et l'exprimer
A10: C - Sciences de la modélisation | B10: 2 | C10: CI
A11: C.1 Savoir identifier les outils utiles pour la résolution du problème
A12: C.2 Connaître, comprendre et savoir faire usage des outils de la modélisation numérique (MEF, VF, DF)
A13: C.3 Être capable d'analyse de critique des modèles, des résultats

Sheet Items sous domaines Sciences 
A1: Objectifs d'apprentissage des Sciences | H1: Remédiation
A4: Propositions d'Items pour les Objectifs d'apprentissage | G4: nv | H4: lien Unisciel ou livre scolaire
B7: Mécanique | D7: Mécanique
B10: Mécanique | C10: Point | D10: Mécanique du point | E10: Distinguer les différents types de force (poids, réaction, frottements (statique et cinétique), tension...). | F10: 1 | G10: =F10 -> 1
B11: Mécanique | C11: Point | E11: Appliquer le PFD avec et sans frottements à un mouvement plan. | F11: 1 | G11: =F11 -> 1
B12: Mécanique | C12: Point | E12: Calculer le travail d'une force. | F12: 1 | G12: =F12 -> 1
B13: Mécanique | C13: Point | E13: Distinguer une force conservative et non conservative. | F13: 1 | G13: =F13 -> 1
B14: Mécanique | C14: Point | E14: Calculer une énergie mécanique, cinétique, potentielle. | F14: 1 | G14: =F14 -> 1
B15: Mécanique | C15: Point | E15: Appliquer le théorème de conservation de l'énergie mécanique. | F15: 1 | G15: =F15 -> 1
B16: Mécanique | C16: Point | E16: Appliquer le théorème de l'énergie cinétique. | F16: 1 | G16: =F16 -> 1
B17: Mécanique | C17: Point | E17: Établir les équations horaires (sans et avec frottements). | F17: 1 | G17: =F17 -> 1
B18: Mécanique | C18: Point | E18: Calculer le moment d’une force. | F18: 1 | G18: =F18 -> 1
B19: Mécanique | C19: Point | E19: Appliquer le PFD avec et sans frottements à un mouvement circulaire. | F19: 1 | G19: =F19 -> 1
B20: Mécanique | C20: Point | E20: Établir une équation différentielle du 1er et 2ème ordre. | F20: 1 | G20: =F20 -> 1
B21: Mécanique | C21: Point | E21: Calculer une force. | F21: 5 | G21: =F21 -> 5
B22: Mécanique | C22: Point | E22: Calculer un moment. | F22: 5 | G22: =F22 -> 5
B23: Mécanique | C23: Point | E23: Calculer une énergie mécanique. | F23: 5 | G23: =F23 -> 5
B24: Mécanique | C24: Mécanisme | D24: Mécanique du solide | E24: Établir le schéma mécanique d'une structure. | F24: 5 | G24: =F24 -> 5
B25: Mécanique | C25: Solide | E25: Appliquer le principe fondamental de la statique. | F25: 5 | G25: =F25 -> 5
B26: Mécanique | C26: Solide | E26: Expliquer l'équilibre statique d'un solide ou d'un ensemble de solides. | F26: 5 | G26: =F26 -> 5
B27: Mécanique | C27: Solide | E27: Appliquer le torseur pour résoudre un problème de statique (PFS). | F27: 5 | G27: =F27 -> 5
B28: Mécanique | C28: Point | E28: Appliquer les lois de Coulomb. | F28: 5 | G28: =F28 -> 5
B29: Mécanique | C29: Solide | E29: Utiliser les liaisons mécaniques usuelles. | F29: 5 | G29: =F29 -> 5
B30: Mécanique | C30: Solide | E30: Résoudre un problème de statique graphique. | F30: 5 | G30: =F30 -> 5
B31: Mécanique | C31: Solide | E31: Appliquer le principe fondamental de la dynamique. | F31: 6 | G31: =F31 -> 6
B32: Mécanique | C32: Solide | E32: Schématiser les actions mécaniques. | F32: 6 | G32: =F32 -> 6
B33: Mécanique | C33: Solide | E33: Calculer une puissance mécanique. | F33: 6 | G33: =F33 -> 6
B34: Mécanique | C34: Solide | E34: Appliquer le théorème de l'énergie cinétique. | F34: 6 | G34: =F34 -> 6
B35: Mécanique | C35: Solide | E35: Utiliser les moments d'inertie équivalents. | F35: 6 | G35: =F35 -> 6
B36: Mécanique | C36: RDM | D36: RDM | E36: Expliquer les notions "contrainte" et "déformation". | F36: 2 | G36: =F36 -> 2
B37: Mécanique | C37: RDM | E37: Interpréter une courbe de traction (domaines élastique, plastique, striction, rupture) et ses données caractéristiques (résistance élastique, résistance max). | F37: 2 | G37: =F37 -> 2
B38: Mécanique | C38: RDM | E38: Calculer un module d’Young à partir d’une courbe de traction. | F38: 2 | G38: =F38 -> 2
B39: Mécanique | C39: RDM | E39: Calculer une contrainte et un allongement. | F39: 2 | G39: =F39 -> 2
B40: Mécanique | C40: RDM | E40: Utiliser la loi de Hooke. | F40: 2 | G40: =F40 -> 2
B41: Mécanique | C41: RDM | E41: Corréler les propriétés mécaniques et thermiques d’un matériau au type de liaison. | F41: 2 | G41: =F41 -> 2
B42: Mécanique | C42: RDM | E42: Discriminer un matériau pour une application. | F42: 2 | G42: =F42 -> 2
B43: Mécanique | C43: RDM | E43: Identifier les liaisons mécaniques (2D) entre solides, internes/externes (appui simple, articulation). | F43: 2 | G43: =F43 -> 2
B44: Mécanique | C44: RDM | E44: Identifier et appliquer les différents types de charges (force ponctuelle, charge linéique). | F44: 2 | G44: =F44 -> 2
B45: Mécanique | C45: RDM | E45: Déterminer le nombre de degrés de liberté d’un système articulé. | F45: 2 | G45: =F45 -> 2
B46: Mécanique | C46: RDM | E46: Utiliser le principe d’action/réaction pour appliquer le PFS. | F46: 2 | G46: =F46 -> 2
...

Sheet Remédiation A3
A1: Aide :
A2: Vous retrouverez dans les onglets votre cursus
A3: Vous retrouverez les éléments évaluables de votre dossier de synthèse avec les chapitres et thèmes sur lesquels vous serez interrogé
A4: Vos révisions sont donc ciblées sur la base de ce référentiel et les AAVs des blocs
A5: Pour les A1 et A3 vous pouvez renseigner vos scores et voir votre progression par rapport au positionnement
A7: Une note supérieure à 10/20 au test de positionnement est attendu au minimum
A9: 2) Insérer vos résultats (nombre de bonnes réponses sur THEIA) dans les cases :
A10: 3) faites vos diagrammes de remédiation sur la base des scores en pourcentage
A11: Mécanique
A12: Compétences | C12: Calculer | D12: Modéliser | E12: Valider | F12: score
A13: Statique du point et du solide | B13: Calculer une action mécanique (force et moment)
B14: Appliquer le principe fondamental de la statique
B15: Utiliser les torseurs pour résoudre un problème de statique du solide
B16: Utiliser la loi de Coulomb
A17: Cinématique du solide | B17: Représenter les liaisons cinématiques
A18: Energétique | B18: Calculer le travail d’une force
B19: Calculer une énergie (cinétique, potentielle, mécanique)
B20: Utiliser les théorèmes énergétiques (théorème de l’énergie cinétique, théorème de l’énergie mécanique)
C21: score
A23: Electricité
A24: Compétences | C24: Calculer | D24: Modéliser | E24: Valider | F24: score
B25: Calculer un courant et une tension à partir de la loi d'Ohm et des lois de Kirchhoff
B26: Calculer la puissance et l'énergie d'un récepteur ou d'un générateur alimenté en courant continu
B27: Calculer une résistance équivalente à partir de résistances en série et/ou en parallèle
C28: score
A30: Energétique
A31: Compétences | C31: Calculer | D31: Modéliser | E31: Valider | F31: score
B32: Décrire un système thermodynamique fermé ou isolé en fonction de ses variables d’état (P, V, T)
B33: Utiliser la loi des GP
B34: Expliquer les différents type de transformations (réversible, isobare, isochore, isotherme, adiabatique)
B35: Utiliser la loi des GP et les lois de Laplace dans le cadre des transformations isobares, isothermes,isochores,adiabatiques réversibles pour trouver le travail d'une transformation
B36: Discuter d'un bilan énergétique en utilisant le 1er principe de la thermodynamique
B37: Décrire et situer les phénomènes de conduction, convection et rayonnement
C38: score

Sheet A1 CPI S1
A1: Objectifs d'apprentissage des sciences physiques | G1: Remédiation
A4: Notions à maîtriser en CPI A1 S1 | G4: lien Unisciel ou livre scolaire
A7: UE du DS | B7: Domaine | C7: Discipline | D7: Chapitres | E7: Thèmes | F7: Utilisation
A8: UE 1.3 : Mécanique | B8: =IF('Items sous domaines Sciences '!G10=1,'Items sous domaines Sciences '!B10,0) -> Mécanique | C8: =IF('Items sous domaines Sciences '!G10=1,'Items sous domaines Sciences '!C10,0) -> Point | D8: =IF('Items sous domaines Sciences '!G10=1,'Items sous domaines Sciences '!D10,0) -> Mécanique du point | E8: =IF('Items sous domaines Sciences '!G10=1,'Items sous domaines Sciences '!E10,0) -> Distinguer les différents types de force (poids, réaction, frottements (statique et cinétique), tension...). | F8: Bloc Mécanique | G8: https://uel.unisciel.fr/physique/meca/meca/co/meca.html
B9: =IF('Items sous domaines Sciences '!G11=1,'Items sous domaines Sciences '!B11,0) -> Mécanique | C9: =IF('Items sous domaines Sciences '!G11=1,'Items sous domaines Sciences '!C11,0) -> Point | D9: =IF('Items sous domaines Sciences '!G11=1,'Items sous domaines Sciences '!D11,0) -> 0 | E9: =IF('Items sous domaines Sciences '!G11=1,'Items sous domaines Sciences '!E11,0) -> Appliquer le PFD avec et sans frottements à un mouvement plan.
B10: =IF('Items sous domaines Sciences '!G12=1,'Items sous domaines Sciences '!B12,0) -> Mécanique | C10: =IF('Items sous domaines Sciences '!G12=1,'Items sous domaines Sciences '!C12,0) -> Point | D10: =IF('Items sous domaines Sciences '!G12=1,'Items sous domaines Sciences '!D12,0) -> 0 | E10: =IF('Items sous domaines Sciences '!G12=1,'Items sous domaines Sciences '!E12,0) -> Calculer le travail d'une force.
B11: =IF('Items sous domaines Sciences '!G13=1,'Items sous domaines Sciences '!B13,0) -> Mécanique | C11: =IF('Items sous domaines Sciences '!G13=1,'Items sous domaines Sciences '!C13,0) -> Point | D11: =IF('Items sous domaines Sciences '!G13=1,'Items sous domaines Sciences '!D13,0) -> 0 | E11: =IF('Items sous domaines Sciences '!G13=1,'Items sous domaines Sciences '!E13,0) -> Distinguer une force conservative et non conservative.
B12: =IF('Items sous domaines Sciences '!G14=1,'Items sous domaines Sciences '!B14,0) -> Mécanique | C12: =IF('Items sous domaines Sciences '!G14=1,'Items sous domaines Sciences '!C14,0) -> Point | D12: =IF('Items sous domaines Sciences '!G14=1,'Items sous domaines Sciences '!D14,0) -> 0 | E12: =IF('Items sous domaines Sciences '!G14=1,'Items sous domaines Sciences '!E14,0) -> Calculer une énergie mécanique, cinétique, potentielle.
B13: =IF('Items sous domaines Sciences '!G15=1,'Items sous domaines Sciences '!B15,0) -> Mécanique | C13: =IF('Items sous domaines Sciences '!G15=1,'Items sous domaines Sciences '!C15,0) -> Point | D13: =IF('Items sous domaines Sciences '!G15=1,'Items sous domaines Sciences '!D15,0) -> 0 | E13: =IF('Items sous domaines Sciences '!G15=1,'Items sous domaines Sciences '!E15,0) -> Appliquer le théorème de conservation de l'énergie mécanique.
B14: =IF('Items sous domaines Sciences '!G16=1,'Items sous domaines Sciences '!B16,0) -> Mécanique | C14: =IF('Items sous domaines Sciences '!G16=1,'Items sous domaines Sciences '!C16,0) -> Point | D14: =IF('Items sous domaines Sciences '!G16=1,'Items sous domaines Sciences '!D16,0) -> 0 | E14: =IF('Items sous domaines Sciences '!G16=1,'Items sous domaines Sciences '!E16,0) -> Appliquer le théorème de l'énergie cinétique.
B15: =IF('Items sous domaines Sciences '!G17=1,'Items sous domaines Sciences '!B17,0) -> Mécanique | C15: =IF('Items sous domaines Sciences '!G17=1,'Items sous domaines Sciences '!C17,0) -> Point | D15: =IF('Items sous domaines Sciences '!G17=1,'Items sous domaines Sciences '!D17,0) -> 0 | E15: =IF('Items sous domaines Sciences '!G17=1,'Items sous domaines Sciences '!E17,0) -> Établir les équations horaires (sans et avec frottements).
B16: =IF('Items sous domaines Sciences '!G18=1,'Items sous domaines Sciences '!B18,0) -> Mécanique | C16: =IF('Items sous domaines Sciences '!G18=1,'Items sous domaines Sciences '!C18,0) -> Point | D16: =IF('Items sous domaines Sciences '!G18=1,'Items sous domaines Sciences '!D18,0) -> 0 | E16: =IF('Items sous domaines Sciences '!G18=1,'Items sous domaines Sciences '!E18,0) -> Calculer le moment d’une force.
B17: =IF('Items sous domaines Sciences '!G19=1,'Items sous domaines Sciences '!B19,0) -> Mécanique | C17: =IF('Items sous domaines Sciences '!G19=1,'Items sous domaines Sciences '!C19,0) -> Point | D17: =IF('Items sous domaines Sciences '!G19=1,'Items sous domaines Sciences '!D19,0) -> 0 | E17: =IF('Items sous domaines Sciences '!G19=1,'Items sous domaines Sciences '!E19,0) -> Appliquer le PFD avec et sans frottements à un mouvement circulaire.
B18: =IF('Items sous domaines Sciences '!G20=1,'Items sous domaines Sciences '!B20,0) -> Mécanique | C18: =IF('Items sous domaines Sciences '!G20=1,'Items sous domaines Sciences '!C20,0) -> Point | D18: =IF('Items sous domaines Sciences '!G20=1,'Items sous domaines Sciences '!D20,0) -> 0 | E18: =IF('Items sous domaines Sciences '!G20=1,'Items sous domaines Sciences '!E20,0) -> Établir une équation différentielle du 1er et 2ème ordre.
B19: =IF('Items sous domaines Sciences '!G21=1,'Items sous domaines Sciences '!B21,0) -> 0 | C19: =IF('Items sous domaines Sciences '!G21=1,'Items sous domaines Sciences '!C21,0) -> 0 | D19: =IF('Items sous domaines Sciences '!G21=1,'Items sous domaines Sciences '!D21,0) -> 0 | E19: =IF('Items sous domaines Sciences '!G21=1,'Items sous domaines Sciences '!E21,0) -> 0
B20: =IF('Items sous domaines Sciences '!G22=1,'Items sous domaines Sciences '!B22,0) -> 0 | C20: =IF('Items sous domaines Sciences '!G22=1,'Items sous domaines Sciences '!C22,0) -> 0 | D20: =IF('Items sous domaines Sciences '!G22=1,'Items sous domaines Sciences '!D22,0) -> 0 | E20: =IF('Items sous domaines Sciences '!G22=1,'Items sous domaines Sciences '!E22,0) -> 0
... B23: =IF('Items sous domaines Sciences '!G25=1,'Items sous domaines Sciences '!B25,0) -> 0 | C23: =IF('Items sous domaines Sciences '!G25=1,'Items sous domaines Sciences '!C25,0) -> 0 | D23: =IF('Items sous domaines Sciences '!G25=1,'Items sous domaines Sciences '!D25,0) -> 0 | E23: =IF('Items sous domaines Sciences '!G25=1,'Items sous domaines Sciences '!E25,0) -> 0
B24: =IF('Items sous domaines Sciences '!G26=1,'Items sous domaines Sciences '!B26,0) -> 0 | C24: =IF('Items sous domaines Sciences '!G26=1,'Items sous domaines Sciences '!C26,0) -> 0 | D24: =IF('Items sous domaines Sciences '!G26=1,'Items sous domaines Sciences '!D26,0) -> 0 | E24: =IF('Items sous domaines Sciences '!G26=1,'Items sous domaines Sciences '!E26,0) -> 0 | F24: =IF('Items sous domaines Sciences '!#REF!=1,'Items sous domaines Sciences '!#REF!,0) -> #REF!
B25: =IF('Items sous domaines Sciences '!G27=1,'Items sous domaines Sciences '!B27,0) -> 0 | C25: =IF('Items sous domaines Sciences '!G27=1,'Items sous domaines Sciences '!C27,0) -> 0 | D25: =IF('Items sous domaines Sciences '!G27=1,'Items sous domaines Sciences '!D27,0) -> 0 | E25: =IF('Items sous domaines Sciences '!G27=1,'Items sous domaines Sciences '!E27,0) -> 0 | F25: =IF('Items sous domaines Sciences '!G78=1,'Items sous domaines Sciences '!#REF!,0) -> 0
A26: Algèbre de Boole | B26: =IF('Items sous domaines Sciences '!G28=1,'Items sous domaines Sciences '!B28,0) -> 0 | C26: =IF('Items sous domaines Sciences '!G28=1,'Items sous domaines Sciences '!C28,0) -> 0 | D26: =IF('Items sous domaines Sciences '!G28=1,'Items sous domaines Sciences '!D28,0) -> 0 | E26: =IF('Items sous domaines Sciences '!G28=1,'Items sous domaines Sciences '!E28,0) -> 0 | F26: Projet Strongbox-Electronique | G26: https://uel.unisciel.fr/mathematiques/logique1/logique1/co/logique1.html
B27: =IF('Items sous domaines Sciences '!G29=1,'Items sous domaines Sciences '!B29,0) -> 0 | C27: =IF('Items sous domaines Sciences '!G29=1,'Items sous domaines Sciences '!C29,0) -> 0 | D27: =IF('Items sous domaines Sciences '!G29=1,'Items sous domaines Sciences '!D29,0) -> 0 | E27: =IF('Items sous domaines Sciences '!G29=1,'Items sous domaines Sciences '!E29,0) -> 0
B28: =IF('Items sous domaines Sciences '!G30=1,'Items sous domaines Sciences '!B30,0) -> 0 | C28: =IF('Items sous domaines Sciences '!G30=1,'Items sous domaines Sciences '!C30,0) -> 0 | D28: =IF('Items sous domaines Sciences '!G30=1,'Items sous domaines Sciences '!D30,0) -> 0 | E28: =IF('Items sous domaines Sciences '!G30=1,'Items sous domaines Sciences '!E30,0) -> 0
B29: =IF('Items sous domaines Sciences '!G31=1,'Items sous domaines Sciences '!B31,0) -> 0 | C29: =IF('Items sous domaines Sciences '!G31=1,'Items sous domaines Sciences '!C31,0) -> 0 | D29: =IF('Items sous domaines Sciences '!G31=1,'Items sous domaines Sciences '!D31,0) -> 0 | E29: =IF('Items sous domaines Sciences '!G31=1,'Items sous domaines Sciences '!E31,0) -> 0
B30: =IF('Items sous domaines Sciences '!G32=1,'Items sous domaines Sciences '!B32,0) -> 0 | C30: =IF('Items sous domaines Sciences '!G32=1,'Items sous domaines Sciences '!C32,0) -> 0 | D30: =IF('Items sous domaines Sciences '!G32=1,'Items sous domaines Sciences '!D32,0) -> 0 | E30: =IF('Items sous domaines Sciences '!G32=1,'Items sous domaines Sciences '!E32,0) -> 0
B31: =IF('Items sous domaines Sciences '!G33=1,'Items sous domaines Sciences '!B33,0) -> 0 | C31: =IF('Items sous domaines Sciences '!G33=1,'Items sous domaines Sciences '!C33,0) -> 0 | D31: =IF('Items sous domaines Sciences '!G33=1,'Items sous domaines Sciences '!D33,0) -> 0 | E31: =IF('Items sous domaines Sciences '!G33=1,'Items sous domaines Sciences '!E33,0) -> 0
B32: =IF('Items sous domaines Sciences '!G34=1,'Items sous domaines Sciences '!B34,0) -> 0 | C32: =IF('Items sous domaines Sciences '!G34=1,'Items sous domaines Sciences '!C34,0) -> 0 | D32: =IF('Items sous domaines Sciences '!G34=1,'Items sous domaines Sciences '!D34,0) -> 0 | E32: =IF('Items sous domaines Sciences '!G34=1,'Items sous domaines Sciences '!E34,0) -> 0
B33: =IF('Items sous domaines Sciences '!G35=1,'Items sous domaines Sciences '!B35,0) -> 0 | C33: =IF('Items sous domaines Sciences '!G35=1,'Items sous domaines Sciences '!C35,0) -> 0 | D33: =IF('Items sous domaines Sciences '!G35=1,'Items sous domaines Sciences '!D35,0) -> 0 | E33: =IF('Items sous domaines Sciences '!G35=1,'Items sous domaines Sciences '!E35,0) -> 0
B34: =IF('Items sous domaines Sciences '!G36=1,'Items sous domaines Sciences '!B36,0) -> 0 | C34: =IF('Items sous domaines Sciences '!G36=1,'Items sous domaines Sciences '!C36,0) -> 0 | D34: =IF('Items sous domaines Sciences '!G36=1,'Items sous domaines Sciences '!D36,0) -> 0 | E34: =IF('Items sous domaines Sciences '!G36=1,'Items sous domaines Sciences '!E36,0) -> 0
B35: =IF('Items sous domaines Sciences '!G37=1,'Items sous domaines Sciences '!B37,0) -> 0 | C35: =IF('Items sous domaines Sciences '!G37=1,'Items sous domaines Sciences '!C37,0) -> 0 | D35: =IF('Items sous domaines Sciences '!G37=1,'Items sous domaines Sciences '!D37,0) -> 0 | E35: =IF('Items sous domaines Sciences '!G37=1,'Items sous domaines Sciences '!E37,0) -> 0
B36: =IF('Items sous domaines Sciences '!G38=1,'Items sous domaines Sciences '!B38,0) -> 0 | C36: =IF('Items sous domaines Sciences '!G38=1,'Items sous domaines Sciences '!C38,0) -> 0 | D36: =IF('Items sous domaines Sciences '!G38=1,'Items sous domaines Sciences '!D38,0) -> 0 | E36: =IF('Items sous domaines Sciences '!G38=1,'Items sous domaines Sciences '!E38,0) -> 0
B37: =IF('Items sous domaines Sciences '!G39=1,'Items sous domaines Sciences '!B39,0) -> 0 | C37: =IF('Items sous domaines Sciences '!G39=1,'Items sous domaines Sciences '!C39,0) -> 0 | D37: =IF('Items sous domaines Sciences '!G39=1,'Items sous domaines Sciences '!D39,0) -> 0 | E37: =IF('Items sous domaines Sciences '!G39=1,'Items sous domaines Sciences '!E39,0) -> 0
B38: =IF('Items sous domaines Sciences '!G40=1,'Items sous domaines Sciences '!B40,0) -> 0 | C38: =IF('Items sous domaines Sciences '!G40=1,'Items sous domaines Sciences '!C40,0) -> 0 | D38: =IF('Items sous domaines Sciences '!G40=1,'Items sous domaines Sciences '!D40,0) -> 0 | E38: =IF('Items sous domaines Sciences '!G40=1,'Items sous domaines Sciences '!E40,0) -> 0
B39: =IF('Items sous domaines Sciences '!G41=1,'Items sous domaines Sciences '!B41,0) -> 0 | C39: =IF('Items sous domaines Sciences '!G41=1,'Items sous domaines Sciences '!C41,0) -> 0 | D39: =IF('Items sous domaines Sciences '!G41=1,'Items sous domaines Sciences '!D41,0) -> 0 | E39: =IF('Items sous domaines Sciences '!G41=1,'Items sous domaines Sciences '!E41,0) -> 0 | F39: =IF('Items sous domaines Sciences '!G207=1,'Items sous domaines Sciences '!#REF!,0) -> 0
A40: Algèbre : Nombres complexes | B40: =IF('Items sous domaines Sciences '!G42=1,'Items sous domaines Sciences '!B42,0) -> 0 | C40: =IF('Items sous domaines Sciences '!G42=1,'Items sous domaines Sciences '!C42,0) -> 0 | D40: =IF('Items sous domaines Sciences '!G42=1,'Items sous domaines Sciences '!D42,0) -> 0 | E40: =IF('Items sous domaines Sciences '!G42=1,'Items sous domaines Sciences '!E42,0) -> 0 | F40: Projet Strongbox-Electronique et ETS | G40: https://uel.unisciel.fr/physique/outils_nancy/outils_nancy_ch04/co/apprendre_ch04.html
B41: =IF('Items sous domaines Sciences '!G43=1,'Items sous domaines Sciences '!B43,0) -> 0 | C41: =IF('Items sous domaines Sciences '!G43=1,'Items sous domaines Sciences '!C43,0) -> 0 | D41: =IF('Items sous domaines Sciences '!G43=1,'Items sous domaines Sciences '!D43,0) -> 0 | E41: =IF('Items sous domaines Sciences '!G43=1,'Items sous domaines Sciences '!E43,0) -> 0
B42: =IF('Items sous domaines Sciences '!G44=1,'Items sous domaines Sciences '!B44,0) -> 0 | C42: =IF('Items sous domaines Sciences '!G44=1,'Items sous domaines Sciences '!C44,0) -> 0 | D42: =IF('Items sous domaines Sciences '!G44=1,'Items sous domaines Sciences '!D44,0) -> 0 | E42: =IF('Items sous domaines Sciences '!G44=1,'Items sous domaines Sciences '!E44,0) -> 0
B43: =IF('Items sous domaines Sciences '!G45=1,'Items sous domaines Sciences '!B45,0) -> 0 | C43: =IF('Items sous domaines Sciences '!G45=1,'Items sous domaines Sciences '!C45,0) -> 0 | D43: =IF('Items sous domaines Sciences '!G45=1,'Items sous domaines Sciences '!D45,0) -> 0 | E43: =IF('Items sous domaines Sciences '!G45=1,'Items sous domaines Sciences '!E45,0) -> 0
B44: =IF('Items sous domaines Sciences '!G46=1,'Items sous domaines Sciences '!B46,0) -> 0 | C44: =IF('Items sous domaines Sciences '!G46=1,'Items sous domaines Sciences '!C46,0) -> 0 | D44: =IF('Items sous domaines Sciences '!G46=1,'Items sous domaines Sciences '!D46,0) -> 0 | E44: =IF('Items sous domaines Sciences '!G46=1,'Items sous domaines Sciences '!E46,0) -> 0
B45: =IF('Items sous domaines Sciences '!G47=1,'Items sous domaines Sciences '!B47,0) -> 0 | C45: =IF('Items sous domaines Sciences '!G47=1,'Items sous domaines Sciences '!C47,0) -> 0 | D45: =IF('Items sous domaines Sciences '!G47=1,'Items sous domaines Sciences '!D47,0) -> 0 | E45: =IF('Items sous domaines Sciences '!G47=1,'Items sous domaines Sciences '!E47,0) -> 0
B46: =IF('Items sous domaines Sciences '!G48=1,'Items sous domaines Sciences '!B48,0) -> 0 | C46: =IF('Items sous domaines Sciences '!G48=1,'Items sous domaines Sciences '!C48,0) -> 0 | D46: =IF('Items sous domaines Sciences '!G48=1,'Items sous domaines Sciences '!D48,0) -> 0 | E46: =IF('Items sous domaines Sciences '!G48=1,'Items sous domaines Sciences '!E48,0) -> 0
...

Sheet A1 CPI S2
A1: Objectifs d'apprentissage des sciences physiques
G3: Remédiation
A4: Notions à maîtriser en CPI A1 S2 (+ onglet A1 CPI S1)
G6: lien Unisciel ou livre scolaire
A7: ='A1 CPI S1'!A7 -> UE du DS | B7: ='A1 CPI S1'!B7 -> Domaine | C7: ='A1 CPI S1'!C7 -> Discipline | D7: ='A1 CPI S1'!D7 -> Chapitres | E7: ='A1 CPI S1'!E7 -> Thèmes | F7: Utilisation
A8: Algèbre : Nombres complexes, arithmétique | B8: =IF('Items sous domaines Sciences '!G10=2,'Items sous domaines Sciences '!B10,0) -> 0 | C8: =IF('Items sous domaines Sciences '!G10=2,'Items sous domaines Sciences '!C10,0) -> 0 | D8: =IF('Items sous domaines Sciences '!G10=2,'Items sous domaines Sciences '!D10,0) -> 0 | E8: =IF('Items sous domaines Sciences '!G10=2,'Items sous domaines Sciences '!E10,0) -> 0 | F8: =IF('Items sous domaines Sciences '!#REF!=2,'Items sous domaines Sciences '!#REF!,0) -> #REF!
B9: =IF('Items sous domaines Sciences '!G11=2,'Items sous domaines Sciences '!B11,0) -> 0 | C9: =IF('Items sous domaines Sciences '!G11=2,'Items sous domaines Sciences '!C11,0) -> 0 | D9: =IF('Items sous domaines Sciences '!G11=2,'Items sous domaines Sciences '!D11,0) -> 0 | E9: =IF('Items sous domaines Sciences '!G11=2,'Items sous domaines Sciences '!E11,0) -> 0 | F9: =IF('Items sous domaines Sciences '!G22=2,'Items sous domaines Sciences '!#REF!,0) -> 0
B10: =IF('Items sous domaines Sciences '!G12=2,'Items sous domaines Sciences '!B12,0) -> 0 | C10: =IF('Items sous domaines Sciences '!G12=2,'Items sous domaines Sciences '!C12,0) -> 0 | D10: =IF('Items sous domaines Sciences '!G12=2,'Items sous domaines Sciences '!D12,0) -> 0 | E10: =IF('Items sous domaines Sciences '!G12=2,'Items sous domaines Sciences '!E12,0) -> 0 | F10: =IF('Items sous domaines Sciences '!G23=2,'Items sous domaines Sciences '!#REF!,0) -> 0
A11: Algèbre : arithmétique | B11: =IF('Items sous domaines Sciences '!G13=2,'Items sous domaines Sciences '!B13,0) -> 0 | C11: =IF('Items sous domaines Sciences '!G13=2,'Items sous domaines Sciences '!C13,0) -> 0 | D11: =IF('Items sous domaines Sciences '!G13=2,'Items sous domaines Sciences '!D13,0) -> 0 | E11: =IF('Items sous domaines Sciences '!G13=2,'Items sous domaines Sciences '!E13,0) -> 0 | F11: ETS | G11: https://uel.unisciel.fr/mathematiques/arithmetique/arithmetique/co/arithmetique.html
B12: =IF('Items sous domaines Sciences '!G14=2,'Items sous domaines Sciences '!B14,0) -> 0 | C12: =IF('Items sous domaines Sciences '!G14=2,'Items sous domaines Sciences '!C14,0) -> 0 | D12: =IF('Items sous domaines Sciences '!G14=2,'Items sous domaines Sciences '!D14,0) -> 0 | E12: =IF('Items sous domaines Sciences '!G14=2,'Items sous domaines Sciences '!E14,0) -> 0
B13: =IF('Items sous domaines Sciences '!G15=2,'Items sous domaines Sciences '!B15,0) -> 0 | C13: =IF('Items sous domaines Sciences '!G15=2,'Items sous domaines Sciences '!C15,0) -> 0 | D13: =IF('Items sous domaines Sciences '!G15=2,'Items sous domaines Sciences '!D15,0) -> 0 | E13: =IF('Items sous domaines Sciences '!G15=2,'Items sous domaines Sciences '!E15,0) -> 0
B14: =IF('Items sous domaines Sciences '!G16=2,'Items sous domaines Sciences '!B16,0) -> 0 | C14: =IF('Items sous domaines Sciences '!G16=2,'Items sous domaines Sciences '!C16,0) -> 0 | D14: =IF('Items sous domaines Sciences '!G16=2,'Items sous domaines Sciences '!D16,0) -> 0 | E14: =IF('Items sous domaines Sciences '!G16=2,'Items sous domaines Sciences '!E16,0) -> 0
B15: =IF('Items sous domaines Sciences '!G17=2,'Items sous domaines Sciences '!B17,0) -> 0 | C15: =IF('Items sous domaines Sciences '!G17=2,'Items sous domaines Sciences '!C17,0) -> 0 | D15: =IF('Items sous domaines Sciences '!G17=2,'Items sous domaines Sciences '!D17,0) -> 0 | E15: =IF('Items sous domaines Sciences '!G17=2,'Items sous domaines Sciences '!E17,0) -> 0 | F15: =IF('Items sous domaines Sciences '!G28=2,'Items sous domaines Sciences '!#REF!,0) -> 0
B16: =IF('Items sous domaines Sciences '!G18=2,'Items sous domaines Sciences '!B18,0) -> 0 | C16: =IF('Items sous domaines Sciences '!G18=2,'Items sous domaines Sciences '!C18,0) -> 0 | D16: =IF('Items sous domaines Sciences '!G18=2,'Items sous domaines Sciences '!D18,0) -> 0 | E16: =IF('Items sous domaines Sciences '!G18=2,'Items sous domaines Sciences '!E18,0) -> 0 | F16: =IF('Items sous domaines Sciences '!G29=2,'Items sous domaines Sciences '!#REF!,0) -> 0
B17: =IF('Items sous domaines Sciences '!G19=2,'Items sous domaines Sciences '!B19,0) -> 0 | C17: =IF('Items sous domaines Sciences '!G19=2,'Items sous domaines Sciences '!C19,0) -> 0 | D17: =IF('Items sous domaines Sciences '!G19=2,'Items sous domaines Sciences '!D19,0) -> 0 | E17: =IF('Items sous domaines Sciences '!G19=2,'Items sous domaines Sciences '!E19,0) -> 0 | F17: =IF('Items sous domaines Sciences '!G30=2,'Items sous domaines Sciences '!#REF!,0) -> 0
B18: =IF('Items sous domaines Sciences '!G20=2,'Items sous domaines Sciences '!B20,0) -> 0 | C18: =IF('Items sous domaines Sciences '!G20=2,'Items sous domaines Sciences '!C20,0) -> 0 | D18: =IF('Items sous domaines Sciences '!G20=2,'Items sous domaines Sciences '!D20,0) -> 0 | E18: =IF('Items sous domaines Sciences '!G20=2,'Items sous domaines Sciences '!E20,0) -> 0 | F18: =IF('Items sous domaines Sciences '!G31=2,'Items sous domaines Sciences '!#REF!,0) -> 0
B19: =IF('Items sous domaines Sciences '!G21=2,'Items sous domaines Sciences '!B21,0) -> 0 | C19: =IF('Items sous domaines Sciences '!G21=2,'Items sous domaines Sciences '!C21,0) -> 0 | D19: =IF('Items sous domaines Sciences '!G21=2,'Items sous domaines Sciences '!D21,0) -> 0 | E19: =IF('Items sous domaines Sciences '!G21=2,'Items sous domaines Sciences '!E21,0) -> 0 | F19: =IF('Items sous domaines Sciences '!G32=2,'Items sous domaines Sciences '!#REF!,0) -> 0
B20: =IF('Items sous domaines Sciences '!G22=2,'Items sous domaines Sciences '!B22,0) -> 0 | C20: =IF('Items sous domaines Sciences '!G22=2,'Items sous domaines Sciences '!C22,0) -> 0 | D20: =IF('Items sous domaines Sciences '!G22=2,'Items sous domaines Sciences '!D22,0) -> 0 | E20: =IF('Items sous domaines Sciences '!G22=2,'Items sous domaines Sciences '!E22,0) -> 0 | F20: =IF('Items sous domaines Sciences '!G33=2,'Items sous domaines Sciences '!#REF!,0) -> 0
B21: =IF('Items sous domaines Sciences '!G23=2,'Items sous domaines Sciences '!B23,0) -> 0 | C21: =IF('Items sous domaines Sciences '!G23=2,'Items sous domaines Sciences '!C23,0) -> 0 | D21: =IF('Items sous domaines Sciences '!G23=2,'Items sous domaines Sciences '!D23,0) -> 0 | E21: =IF('Items sous domaines Sciences '!G23=2,'Items sous domaines Sciences '!E23,0) -> 0 | F21: =IF('Items sous domaines Sciences '!G34=2,'Items sous domaines Sciences '!#REF!,0) -> 0
B22: =IF('Items sous domaines Sciences '!G24=2,'Items sous domaines Sciences '!B24,0) -> 0 | C22: =IF('Items sous domaines Sciences '!G24=2,'Items sous domaines Sciences '!C24,0) -> 0 | D22: =IF('Items sous domaines Sciences '!G24=2,'Items sous domaines Sciences '!D24,0) -> 0 | E22: =IF('Items sous domaines Sciences '!G24=2,'Items sous domaines Sciences '!E24,0) -> 0 | F22: =IF('Items sous domaines Sciences '!G35=2,'Items sous domaines Sciences '!#REF!,0) -> 0
B23: =IF('Items sous domaines Sciences '!G25=2,'Items sous domaines Sciences '!B25,0) -> 0 | C23: =IF('Items sous domaines Sciences '!G25=2,'Items sous domaines Sciences '!C25,0) -> 0 | D23: =IF('Items sous domaines Sciences '!G25=2,'Items sous domaines Sciences '!D25,0) -> 0 | E23: =IF('Items sous domaines Sciences '!G25=2,'Items sous domaines Sciences '!E25,0) -> 0 | F23: =IF('Items sous domaines Sciences '!#REF!=2,'Items sous domaines Sciences '!#REF!,0) -> #REF!
B24: =IF('Items sous domaines Sciences '!G26=2,'Items sous domaines Sciences '!B26,0) -> 0 | C24: =IF('Items sous domaines Sciences '!G26=2,'Items sous domaines Sciences '!C26,0) -> 0 | D24: =IF('Items sous domaines Sciences '!G26=2,'Items sous domaines Sciences '!D26,0) -> 0 | E24: =IF('Items sous domaines Sciences '!G26=2,'Items sous domaines Sciences '!E26,0) -> 0 | F24: =IF('Items sous domaines Sciences '!#REF!=2,'Items sous domaines Sciences '!#REF!,0) -> #REF!
B25: =IF('Items sous domaines Sciences '!G27=2,'Items sous domaines Sciences '!B27,0) -> 0 | C25: =IF('Items sous domaines Sciences '!G27=2,'Items sous domaines Sciences '!C27,0) -> 0 | D25: =IF('Items sous domaines Sciences '!G27=2,'Items sous domaines Sciences '!D27,0) -> 0 | E25: =IF('Items sous domaines Sciences '!G27=2,'Items sous domaines Sciences '!E27,0) -> 0 | F25: =IF('Items sous domaines Sciences '!G78=2,'Items sous domaines Sciences '!#REF!,0) -> 0
B26: =IF('Items sous domaines Sciences '!G28=2,'Items sous domaines Sciences '!B28,0) -> 0 | C26: =IF('Items sous domaines Sciences '!G28=2,'Items sous domaines Sciences '!C28,0) -> 0 | D26: =IF('Items sous domaines Sciences '!G28=2,'Items sous domaines Sciences '!D28,0) -> 0 | E26: =IF('Items sous domaines Sciences '!G28=2,'Items sous domaines Sciences '!E28,0) -> 0 | F26: =IF('Items sous domaines Sciences '!G108=2,'Items sous domaines Sciences '!#REF!,0) -> 0
B27: =IF('Items sous domaines Sciences '!G29=2,'Items sous domaines Sciences '!B29,0) -> 0 | C27: =IF('Items sous domaines Sciences '!G29=2,'Items sous domaines Sciences '!C29,0) -> 0 | D27: =IF('Items sous domaines Sciences '!G29=2,'Items sous domaines Sciences '!D29,0) -> 0 | E27: =IF('Items sous domaines Sciences '!G29=2,'Items sous domaines Sciences '!E29,0) -> 0 | F27: =IF('Items sous domaines Sciences '!G109=2,'Items sous domaines Sciences '!#REF!,0) -> 0
B28: =IF('Items sous domaines Sciences '!G30=2,'Items sous domaines Sciences '!B30,0) -> 0 | C28: =IF('Items sous domaines Sciences '!G30=2,'Items sous domaines Sciences '!C30,0) -> 0 | D28: =IF('Items sous domaines Sciences '!G30=2,'Items sous domaines Sciences '!D30,0) -> 0 | E28: =IF('Items sous domaines Sciences '!G30=2,'Items sous domaines Sciences '!E30,0) -> 0 | F28: =IF('Items sous domaines Sciences '!G110=2,'Items sous domaines Sciences '!#REF!,0) -> 0
B29: =IF('Items sous domaines Sciences '!G31=2,'Items sous domaines Sciences '!B31,0) -> 0 | C29: =IF('Items sous domaines Sciences '!G31=2,'Items sous domaines Sciences '!C31,0) -> 0 | D29: =IF('Items sous domaines Sciences '!G31=2,'Items sous domaines Sciences '!D31,0) -> 0 | E29: =IF('Items sous domaines Sciences '!G31=2,'Items sous domaines Sciences '!E31,0) -> 0 | F29: =IF('Items sous domaines Sciences '!G111=2,'Items sous domaines Sciences '!#REF!,0) -> 0
A30: Théorie des ensembles | B30: =IF('Items sous domaines Sciences '!G32=2,'Items sous domaines Sciences '!B32,0) -> 0 | C30: =IF('Items sous domaines Sciences '!G32=2,'Items sous domaines Sciences '!C32,0) -> 0 | D30: =IF('Items sous domaines Sciences '!G32=2,'Items sous domaines Sciences '!D32,0) -> 0 | E30: =IF('Items sous domaines Sciences '!G32=2,'Items sous domaines Sciences '!E32,0) -> 0 | F30: Projet BDD
B31: =IF('Items sous domaines Sciences '!G33=2,'Items sous domaines Sciences '!B33,0) -> 0 | C31: =IF('Items sous domaines Sciences '!G33=2,'Items sous domaines Sciences '!C33,0) -> 0 | D31: =IF('Items sous domaines Sciences '!G33=2,'Items sous domaines Sciences '!D33,0) -> 0 | E31: =IF('Items sous domaines Sciences '!G33=2,'Items sous domaines Sciences '!E33,0) -> 0
B32: =IF('Items sous domaines Sciences '!G34=2,'Items sous domaines Sciences '!B34,0) -> 0 | C32: =IF('Items sous domaines Sciences '!G34=2,'Items sous domaines Sciences '!C34,0) -> 0 | D32: =IF('Items sous domaines Sciences '!G34=2,'Items sous domaines Sciences '!D34,0) -> 0 | E32: =IF('Items sous domaines Sciences '!G34=2,'Items sous domaines Sciences '!E34,0) -> 0 | F32: =IF('Items sous domaines Sciences '!G130=2,'Items sous domaines Sciences '!#REF!,0) -> 0
B33: =IF('Items sous domaines Sciences '!G35=2,'Items sous domaines Sciences '!B35,0) -> 0 | C33: =IF('Items sous domaines Sciences '!G35=2,'Items sous domaines Sciences '!C35,0) -> 0 | D33: =IF('Items sous domaines Sciences '!G35=2,'Items sous domaines Sciences '!D35,0) -> 0 | E33: =IF('Items sous domaines Sciences '!G35=2,'Items sous domaines Sciences '!E35,0) -> 0 | F33: =IF('Items sous domaines Sciences '!G131=2,'Items sous domaines Sciences '!#REF!,0) -> 0
A34: UE 2.4 : Thermodynamique et thermique | B34: =IF('Items sous domaines Sciences '!G36=2,'Items sous domaines Sciences '!B36,0) -> Mécanique | C34: =IF('Items sous domaines Sciences '!G36=2,'Items sous domaines Sciences '!C36,0) -> RDM | D34: =IF('Items sous domaines Sciences '!G36=2,'Items sous domaines Sciences '!D36,0) -> RDM | E34: =IF('Items sous domaines Sciences '!G36=2,'Items sous domaines Sciences '!E36,0) -> Expliquer les notions "contrainte" et "déformation". | F34: Bloc BTP | G34: https://uel.unisciel.fr/physique/meca/meca/co/meca.html
B35: =IF('Items sous domaines Sciences '!G37=2,'Items sous domaines Sciences '!B37,0) -> Mécanique | C35: =IF('Items sous domaines Sciences '!G37=2,'Items sous domaines Sciences '!C37,0) -> RDM | D35: =IF('Items sous domaines Sciences '!G37=2,'Items sous domaines Sciences '!D37,0) -> 0 | E35: =IF('Items sous domaines Sciences '!G37=2,'Items sous domaines Sciences '!E37,0) -> Interpréter une courbe de traction (domaines élastique, plastique, striction, rupture) et ses données caractéristiques (résistance élastique, résistance max).
B36: =IF('Items sous domaines Sciences '!G38=2,'Items sous domaines Sciences '!B38,0) -> Mécanique | C36: =IF('Items sous domaines Sciences '!G38=2,'Items sous domaines Sciences '!C38,0) -> RDM | D36: =IF('Items sous domaines Sciences '!G38=2,'Items sous domaines Sciences '!D38,0) -> 0 | E36: =IF('Items sous domaines Sciences '!G38=2,'Items sous domaines Sciences '!E38,0) -> Calculer un module d’Young à partir d’une courbe de traction.
B37: =IF('Items sous domaines Sciences '!G39=2,'Items sous domaines Sciences '!B39,0) -> Mécanique | C37: =IF('Items sous domaines Sciences '!G39=2,'Items sous domaines Sciences '!C39,0) -> RDM | D37: =IF('Items sous domaines Sciences '!G39=2,'Items sous domaines Sciences '!D39,0) -> 0 | E37: =IF('Items sous domaines Sciences '!G39=2,'Items sous domaines Sciences '!E39,0) -> Calculer une contrainte et un allongement.
B38: =IF('Items sous domaines Sciences '!G40=2,'Items sous domaines Sciences '!B40,0) -> Mécanique | C38: =IF('Items sous domaines Sciences '!G40=2,'Items sous domaines Sciences '!C40,0) -> RDM | D38: =IF('Items sous domaines Sciences '!G40=2,'Items sous domaines Sciences '!D40,0) -> 0 | E38: =IF('Items sous domaines Sciences '!G40=2,'Items sous domaines Sciences '!E40,0) -> Utiliser la loi de Hooke.
B39: =IF('Items sous domaines Sciences '!G41=2,'Items sous domaines Sciences '!B41,0) -> Mécanique | C39: =IF('Items sous domaines Sciences '!G41=2,'Items sous domaines Sciences '!C41,0) -> RDM | D39: =IF('Items sous domaines Sciences '!G41=2,'Items sous domaines Sciences '!D41,0) -> 0 | E39: =IF('Items sous domaines Sciences '!G41=2,'Items sous domaines Sciences '!E41,0) -> Corréler les propriétés mécaniques et thermiques d’un matériau au type de liaison.
B40: =IF('Items sous domaines Sciences '!G42=2,'Items sous domaines Sciences '!B42,0) -> Mécanique | C40: =IF('Items sous domaines Sciences '!G42=2,'Items sous domaines Sciences '!C42,0) -> RDM | D40: =IF('Items sous domaines Sciences '!G42=2,'Items sous domaines Sciences '!D42,0) -> 0 | E40: =IF('Items sous domaines Sciences '!G42=2,'Items sous domaines Sciences '!E42,0) -> Discriminer un matériau pour une application.
B41: =IF('Items sous domaines Sciences '!G43=2,'Items sous domaines Sciences '!B43,0) -> Mécanique | C41: =IF('Items sous domaines Sciences '!G43=2,'Items sous domaines Sciences '!C43,0) -> RDM | D41: =IF('Items sous domaines Sciences '!G43=2,'Items sous domaines Sciences '!D43,0) -> 0 | E41: =IF('Items sous domaines Sciences '!G43=2,'Items sous domaines Sciences '!E43,0) -> Identifier les liaisons mécaniques (2D) entre solides, internes/externes (appui simple, articulation).
B42: =IF('Items sous domaines Sciences '!G44=2,'Items sous domaines Sciences '!B44,0) -> Mécanique | C42: =IF('Items sous domaines Sciences '!G44=2,'Items sous domaines Sciences '!C44,0) -> RDM | D42: =IF('Items sous domaines Sciences '!G44=2,'Items sous domaines Sciences '!D44,0) -> 0 | E42: =IF('Items sous domaines Sciences '!G44=2,'Items sous domaines Sciences '!E44,0) -> Identifier et appliquer les différents types de charges (force ponctuelle, charge linéique).
...

Sheet A2 CPI Géné  S3 
A1: Objectifs d'apprentissage des sciences physiques
G3: Remédiation
A4: Notions à maîtriser en A2 (en révisant le socle A1)
G6: lien Unisciel ou livre scolaire
A7: ='A1 CPI S1'!A7 -> UE du DS | B7: ='A1 CPI S1'!B7 -> Domaine | C7: ='A1 CPI S1'!C7 -> Discipline | D7: ='A1 CPI S1'!D7 -> Chapitres | E7: ='A1 CPI S1'!E7 -> Thèmes | F7: ='A1 CPI S1'!F7 -> Utilisation
A8: UE 3.3 : Thermique et Mécanique des fluides | B8: =IF('Items sous domaines Sciences '!G10=3,'Items sous domaines Sciences '!B10,0) -> 0 | C8: =IF('Items sous domaines Sciences '!G10=3,'Items sous domaines Sciences '!C10,0) -> 0 | D8: =IF('Items sous domaines Sciences '!G10=3,'Items sous domaines Sciences '!D10,0) -> 0 | E8: =IF('Items sous domaines Sciences '!G10=3,'Items sous domaines Sciences '!E10,0) -> 0 | F8: =IF('Items sous domaines Sciences '!#REF!=1,'Items sous domaines Sciences '!#REF!,0) -> #REF!
B9: =IF('Items sous domaines Sciences '!G11=3,'Items sous domaines Sciences '!B11,0) -> 0 | C9: =IF('Items sous domaines Sciences '!G11=3,'Items sous domaines Sciences '!C11,0) -> 0 | D9: =IF('Items sous domaines Sciences '!G11=3,'Items sous domaines Sciences '!D11,0) -> 0 | E9: =IF('Items sous domaines Sciences '!G11=3,'Items sous domaines Sciences '!E11,0) -> 0 | F9: =IF('Items sous domaines Sciences '!G22=1,'Items sous domaines Sciences '!#REF!,0) -> 0
B10: =IF('Items sous domaines Sciences '!G12=3,'Items sous domaines Sciences '!B12,0) -> 0 | C10: =IF('Items sous domaines Sciences '!G12=3,'Items sous domaines Sciences '!C12,0) -> 0 | D10: =IF('Items sous domaines Sciences '!G12=3,'Items sous domaines Sciences '!D12,0) -> 0 | E10: =IF('Items sous domaines Sciences '!G12=3,'Items sous domaines Sciences '!E12,0) -> 0 | F10: =IF('Items sous domaines Sciences '!G23=1,'Items sous domaines Sciences '!#REF!,0) -> 0
B11: =IF('Items sous domaines Sciences '!G13=3,'Items sous domaines Sciences '!B13,0) -> 0 | C11: =IF('Items sous domaines Sciences '!G13=3,'Items sous domaines Sciences '!C13,0) -> 0 | D11: =IF('Items sous domaines Sciences '!G13=3,'Items sous domaines Sciences '!D13,0) -> 0 | E11: =IF('Items sous domaines Sciences '!G13=3,'Items sous domaines Sciences '!E13,0) -> 0 | F11: =IF('Items sous domaines Sciences '!G24=1,'Items sous domaines Sciences '!#REF!,0) -> 0
B12: =IF('Items sous domaines Sciences '!G14=3,'Items sous domaines Sciences '!B14,0) -> 0 | C12: =IF('Items sous domaines Sciences '!G14=3,'Items sous domaines Sciences '!C14,0) -> 0 | D12: =IF('Items sous domaines Sciences '!G14=3,'Items sous domaines Sciences '!D14,0) -> 0 | E12: =IF('Items sous domaines Sciences '!G14=3,'Items sous domaines Sciences '!E14,0) -> 0 | F12: =IF('Items sous domaines Sciences '!G25=1,'Items sous domaines Sciences '!#REF!,0) -> 0
B13: =IF('Items sous domaines Sciences '!G15=3,'Items sous domaines Sciences '!B15,0) -> 0 | C13: =IF('Items sous domaines Sciences '!G15=3,'Items sous domaines Sciences '!C15,0) -> 0 | D13: =IF('Items sous domaines Sciences '!G15=3,'Items sous domaines Sciences '!D15,0) -> 0 | E13: =IF('Items sous domaines Sciences '!G15=3,'Items sous domaines Sciences '!E15,0) -> 0 | F13: =IF('Items sous domaines Sciences '!G26=1,'Items sous domaines Sciences '!#REF!,0) -> 0
B14: =IF('Items sous domaines Sciences '!G16=3,'Items sous domaines Sciences '!B16,0) -> 0 | C14: =IF('Items sous domaines Sciences '!G16=3,'Items sous domaines Sciences '!C16,0) -> 0 | D14: =IF('Items sous domaines Sciences '!G16=3,'Items sous domaines Sciences '!D16,0) -> 0 | E14: =IF('Items sous domaines Sciences '!G16=3,'Items sous domaines Sciences '!E16,0) -> 0 | F14: =IF('Items sous domaines Sciences '!G27=1,'Items sous domaines Sciences '!#REF!,0) -> 0
B15: =IF('Items sous domaines Sciences '!G17=3,'Items sous domaines Sciences '!B17,0) -> 0 | C15: =IF('Items sous domaines Sciences '!G17=3,'Items sous domaines Sciences '!C17,0) -> 0 | D15: =IF('Items sous domaines Sciences '!G17=3,'Items sous domaines Sciences '!D17,0) -> 0 | E15: =IF('Items sous domaines Sciences '!G17=3,'Items sous domaines Sciences '!E17,0) -> 0 | F15: =IF('Items sous domaines Sciences '!G28=1,'Items sous domaines Sciences '!#REF!,0) -> 0
B16: =IF('Items sous domaines Sciences '!G18=3,'Items sous domaines Sciences '!B18,0) -> 0 | C16: =IF('Items sous domaines Sciences '!G18=3,'Items sous domaines Sciences '!C18,0) -> 0 | D16: =IF('Items sous domaines Sciences '!G18=3,'Items sous domaines Sciences '!D18,0) -> 0 | E16: =IF('Items sous domaines Sciences '!G18=3,'Items sous domaines Sciences '!E18,0) -> 0 | F16: =IF('Items sous domaines Sciences '!G29=1,'Items sous domaines Sciences '!#REF!,0) -> 0
B17: =IF('Items sous domaines Sciences '!G19=3,'Items sous domaines Sciences '!B19,0) -> 0 | C17: =IF('Items sous domaines Sciences '!G19=3,'Items sous domaines Sciences '!C19,0) -> 0 | D17: =IF('Items sous domaines Sciences '!G19=3,'Items sous domaines Sciences '!D19,0) -> 0 | E17: =IF('Items sous domaines Sciences '!G19=3,'Items sous domaines Sciences '!E19,0) -> 0 | F17: =IF('Items sous domaines Sciences '!G30=1,'Items sous domaines Sciences '!#REF!,0) -> 0
B18: =IF('Items sous domaines Sciences '!G20=3,'Items sous domaines Sciences '!B20,0) -> 0 | C18: =IF('Items sous domaines Sciences '!G20=3,'Items sous domaines Sciences '!C20,0) -> 0 | D18: =IF('Items sous domaines Sciences '!G20=3,'Items sous domaines Sciences '!D20,0) -> 0 | E18: =IF('Items sous domaines Sciences '!G20=3,'Items sous domaines Sciences '!E20,0) -> 0 | F18: =IF('Items sous domaines Sciences '!G31=1,'Items sous domaines Sciences '!#REF!,0) -> 0
B19: =IF('Items sous domaines Sciences '!G21=3,'Items sous domaines Sciences '!B21,0) -> 0 | C19: =IF('Items sous domaines Sciences '!G21=3,'Items sous domaines Sciences '!C21,0) -> 0 | D19: =IF('Items sous domaines Sciences '!G21=3,'Items sous domaines Sciences '!D21,0) -> 0 | E19: =IF('Items sous domaines Sciences '!G21=3,'Items sous domaines Sciences '!E21,0) -> 0 | F19: =IF('Items sous domaines Sciences '!G32=1,'Items sous domaines Sciences '!#REF!,0) -> 0
B20: =IF('Items sous domaines Sciences '!G22=3,'Items sous domaines Sciences '!B22,0) -> 0 | C20: =IF('Items sous domaines Sciences '!G22=3,'Items sous domaines Sciences '!C22,0) -> 0 | D20: =IF('Items sous domaines Sciences '!G22=3,'Items sous domaines Sciences '!D22,0) -> 0 | E20: =IF('Items sous domaines Sciences '!G22=3,'Items sous domaines Sciences '!E22,0) -> 0 | F20: =IF('Items sous domaines Sciences '!G33=1,'Items sous domaines Sciences '!#REF!,0) -> 0
... B22: =IF('Items sous domaines Sciences '!G24=3,'Items sous domaines Sciences '!B24,0) -> 0 | C22: =IF('Items sous domaines Sciences '!G24=3,'Items sous domaines Sciences '!C24,0) -> 0 | D22: =IF('Items sous domaines Sciences '!G24=3,'Items sous domaines Sciences '!D24,0) -> 0 | E22: =IF('Items sous domaines Sciences '!G24=3,'Items sous domaines Sciences '!E24,0) -> 0 | F22: =IF('Items sous domaines Sciences '!G35=1,'Items sous domaines Sciences '!#REF!,0) -> 0
B23: =IF('Items sous domaines Sciences '!G25=3,'Items sous domaines Sciences '!B25,0) -> 0 | C23: =IF('Items sous domaines Sciences '!G25=3,'Items sous domaines Sciences '!C25,0) -> 0 | D23: =IF('Items sous domaines Sciences '!G25=3,'Items sous domaines Sciences '!D25,0) -> 0 | E23: =IF('Items sous domaines Sciences '!G25=3,'Items sous domaines Sciences '!E25,0) -> 0 | F23: =IF('Items sous domaines Sciences '!#REF!=1,'Items sous domaines Sciences '!#REF!,0) -> #REF!
B24: =IF('Items sous domaines Sciences '!G26=3,'Items sous domaines Sciences '!B26,0) -> 0 | C24: =IF('Items sous domaines Sciences '!G26=3,'Items sous domaines Sciences '!C26,0) -> 0 | D24: =IF('Items sous domaines Sciences '!G26=3,'Items sous domaines Sciences '!D26,0) -> 0 | E24: =IF('Items sous domaines Sciences '!G26=3,'Items sous domaines Sciences '!E26,0) -> 0 | F24: =IF('Items sous domaines Sciences '!#REF!=1,'Items sous domaines Sciences '!#REF!,0) -> #REF!
B25: =IF('Items sous domaines Sciences '!G27=3,'Items sous domaines Sciences '!B27,0) -> 0 | C25: =IF('Items sous domaines Sciences '!G27=3,'Items sous domaines Sciences '!C27,0) -> 0 | D25: =IF('Items sous domaines Sciences '!G27=3,'Items sous domaines Sciences '!D27,0) -> 0 | E25: =IF('Items sous domaines Sciences '!G27=3,'Items sous domaines Sciences '!E27,0) -> 0 | F25: =IF('Items sous domaines Sciences '!G78=1,'Items sous domaines Sciences '!#REF!,0) -> 0
B26: =IF('Items sous domaines Sciences '!G28=3,'Items sous domaines Sciences '!B28,0) -> 0 | C26: =IF('Items sous domaines Sciences '!G28=3,'Items sous domaines Sciences '!C28,0) -> 0 | D26: =IF('Items sous domaines Sciences '!G28=3,'Items sous domaines Sciences '!D28,0) -> 0 | E26: =IF('Items sous domaines Sciences '!G28=3,'Items sous domaines Sciences '!E28,0) -> 0 | F26: =IF('Items sous domaines Sciences '!G108=1,'Items sous domaines Sciences '!#REF!,0) -> 0
B27: =IF('Items sous domaines Sciences '!G29=3,'Items sous domaines Sciences '!B29,0) -> 0 | C27: =IF('Items sous domaines Sciences '!G29=3,'Items sous domaines Sciences '!C29,0) -> 0 | D27: =IF('Items sous domaines Sciences '!G29=3,'Items sous domaines Sciences '!D29,0) -> 0 | E27: =IF('Items sous domaines Sciences '!G29=3,'Items sous domaines Sciences '!E29,0) -> 0 | F27: =IF('Items sous domaines Sciences '!G109=1,'Items sous domaines Sciences '!#REF!,0) -> 0
B28: =IF('Items sous domaines Sciences '!G30=3,'Items sous domaines Sciences '!B30,0) -> 0 | C28: =IF('Items sous domaines Sciences '!G30=3,'Items sous domaines Sciences '!C30,0) -> 0 | D28: =IF('Items sous domaines Sciences '!G30=3,'Items sous domaines Sciences '!D30,0) -> 0 | E28: =IF('Items sous domaines Sciences '!G30=3,'Items sous domaines Sciences '!E30,0) -> 0 | F28: =IF('Items sous domaines Sciences '!G110=1,'Items sous domaines Sciences '!#REF!,0) -> 0
B29: =IF('Items sous domaines Sciences '!G31=3,'Items sous domaines Sciences '!B31,0) -> 0 | C29: =IF('Items sous domaines Sciences '!G31=3,'Items sous domaines Sciences '!C31,0) -> 0 | D29: =IF('Items sous domaines Sciences '!G31=3,'Items sous domaines Sciences '!D31,0) -> 0 | E29: =IF('Items sous domaines Sciences '!G31=3,'Items sous domaines Sciences '!E31,0) -> 0 | F29: =IF('Items sous domaines Sciences '!G111=1,'Items sous domaines Sciences '!#REF!,0) -> 0
B30: =IF('Items sous domaines Sciences '!G32=3,'Items sous domaines Sciences '!B32,0) -> 0 | C30: =IF('Items sous domaines Sciences '!G32=3,'Items sous domaines Sciences '!C32,0) -> 0 | D30: =IF('Items sous domaines Sciences '!G32=3,'Items sous domaines Sciences '!D32,0) -> 0 | E30: =IF('Items sous domaines Sciences '!G32=3,'Items sous domaines Sciences '!E32,0) -> 0 | F30: =IF('Items sous domaines Sciences '!G112=1,'Items sous domaines Sciences '!#REF!,0) -> 0
B31: =IF('Items sous domaines Sciences '!G33=3,'Items sous domaines Sciences '!B33,0) -> 0 | C31: =IF('Items sous domaines Sciences '!G33=3,'Items sous domaines Sciences '!C33,0) -> 0 | D31: =IF('Items sous domaines Sciences '!G33=3,'Items sous domaines Sciences '!D33,0) -> 0 | E31: =IF('Items sous domaines Sciences '!G33=3,'Items sous domaines Sciences '!E33,0) -> 0 | F31: =IF('Items sous domaines Sciences '!G129=1,'Items sous domaines Sciences '!#REF!,0) -> 0
B32: =IF('Items sous domaines Sciences '!G34=3,'Items sous domaines Sciences '!B34,0) -> 0 | C32: =IF('Items sous domaines Sciences '!G34=3,'Items sous domaines Sciences '!C34,0) -> 0 | D32: =IF('Items sous domaines Sciences '!G34=3,'Items sous domaines Sciences '!D34,0) -> 0 | E32: =IF('Items sous domaines Sciences '!G34=3,'Items sous domaines Sciences '!E34,0) -> 0 | F32: =IF('Items sous domaines Sciences '!G130=1,'Items sous domaines Sciences '!#REF!,0) -> 0
B33: =IF('Items sous domaines Sciences '!G35=3,'Items sous domaines Sciences '!B35,0) -> 0 | C33: =IF('Items sous domaines Sciences '!G35=3,'Items sous domaines Sciences '!C35,0) -> 0 | D33: =IF('Items sous domaines Sciences '!G35=3,'Items sous domaines Sciences '!D35,0) -> 0 | E33: =IF('Items sous domaines Sciences '!G35=3,'Items sous domaines Sciences '!E35,0) -> 0 | F33: =IF('Items sous domaines Sciences '!G131=1,'Items sous domaines Sciences '!#REF!,0) -> 0
B34: =IF('Items sous domaines Sciences '!G36=3,'Items sous domaines Sciences '!B36,0) -> 0 | C34: =IF('Items sous domaines Sciences '!G36=3,'Items sous domaines Sciences '!C36,0) -> 0 | D34: =IF('Items sous domaines Sciences '!G36=3,'Items sous domaines Sciences '!D36,0) -> 0 | E34: =IF('Items sous domaines Sciences '!G36=3,'Items sous domaines Sciences '!E36,0) -> 0 | F34: =IF('Items sous domaines Sciences '!G132=1,'Items sous domaines Sciences '!#REF!,0) -> 0
B35: =IF('Items sous domaines Sciences '!G37=3,'Items sous domaines Sciences '!B37,0) -> 0 | C35: =IF('Items sous domaines Sciences '!G37=3,'Items sous domaines Sciences '!C37,0) -> 0 | D35: =IF('Items sous domaines Sciences '!G37=3,'Items sous domaines Sciences '!D37,0) -> 0 | E35: =IF('Items sous domaines Sciences '!G37=3,'Items sous domaines Sciences '!E37,0) -> 0 | F35: =IF('Items sous domaines Sciences '!G182=1,'Items sous domaines Sciences '!#REF!,0) -> 0
B36: =IF('Items sous domaines Sciences '!G38=3,'Items sous domaines Sciences '!B38,0) -> 0 | C36: =IF('Items sous domaines Sciences '!G38=3,'Items sous domaines Sciences '!C38,0) -> 0 | D36: =IF('Items sous domaines Sciences '!G38=3,'Items sous domaines Sciences '!D38,0) -> 0 | E36: =IF('Items sous domaines Sciences '!G38=3,'Items sous domaines Sciences '!E38,0) -> 0 | F36: =IF('Items sous domaines Sciences '!G192=1,'Items sous domaines Sciences '!#REF!,0) -> 0
B37: =IF('Items sous domaines Sciences '!G39=3,'Items sous domaines Sciences '!B39,0) -> 0 | C37: =IF('Items sous domaines Sciences '!G39=3,'Items sous domaines Sciences '!C39,0) -> 0 | D37: =IF('Items sous domaines Sciences '!G39=3,'Items sous domaines Sciences '!D39,0) -> 0 | E37: =IF('Items sous domaines Sciences '!G39=3,'Items sous domaines Sciences '!E39,0) -> 0 | F37: =IF('Items sous domaines Sciences '!G193=1,'Items sous domaines Sciences '!#REF!,0) -> 0
B38: =IF('Items sous domaines Sciences '!G40=3,'Items sous domaines Sciences '!B40,0) -> 0 | C38: =IF('Items sous domaines Sciences '!G40=3,'Items sous domaines Sciences '!C40,0) -> 0 | D38: =IF('Items sous domaines Sciences '!G40=3,'Items sous domaines Sciences '!D40,0) -> 0 | E38: =IF('Items sous domaines Sciences '!G40=3,'Items sous domaines Sciences '!E40,0) -> 0 | F38: =IF('Items sous domaines Sciences '!G194=1,'Items sous domaines Sciences '!#REF!,0) -> 0
B39: =IF('Items sous domaines Sciences '!G41=3,'Items sous domaines Sciences '!B41,0) -> 0 | C39: =IF('Items sous domaines Sciences '!G41=3,'Items sous domaines Sciences '!C41,0) -> 0 | D39: =IF('Items sous domaines Sciences '!G41=3,'Items sous domaines Sciences '!D41,0) -> 0 | E39: =IF('Items sous domaines Sciences '!G41=3,'Items sous domaines Sciences '!E41,0) -> 0 | F39: =IF('Items sous domaines Sciences '!G207=1,'Items sous domaines Sciences '!#REF!,0) -> 0
B40: =IF('Items sous domaines Sciences '!G42=3,'Items sous domaines Sciences '!B42,0) -> 0 | C40: =IF('Items sous domaines Sciences '!G42=3,'Items sous domaines Sciences '!C42,0) -> 0 | D40: =IF('Items sous domaines Sciences '!G42=3,'Items sous domaines Sciences '!D42,0) -> 0 | E40: =IF('Items sous domaines Sciences '!G42=3,'Items sous domaines Sciences '!E42,0) -> 0 | F40: Projet Mécanique des fluides | G40: https://uel.unisciel.fr/physique/meca/meca/co/meca.html
B41: =IF('Items sous domaines Sciences '!G43=3,'Items sous domaines Sciences '!B43,0) -> 0 | C41: =IF('Items sous domaines Sciences '!G43=3,'Items sous domaines Sciences '!C43,0) -> 0 | D41: =IF('Items sous domaines Sciences '!G43=3,'Items sous domaines Sciences '!D43,0) -> 0 | E41: =IF('Items sous domaines Sciences '!G43=3,'Items sous domaines Sciences '!E43,0) -> 0
B42: =IF('Items sous domaines Sciences '!G44=3,'Items sous domaines Sciences '!B44,0) -> 0 | C42: =IF('Items sous domaines Sciences '!G44=3,'Items sous domaines Sciences '!C44,0) -> 0 | D42: =IF('Items sous domaines Sciences '!G44=3,'Items sous domaines Sciences '!D44,0) -> 0 | E42: =IF('Items sous domaines Sciences '!G44=3,'Items sous domaines Sciences '!E44,0) -> 0
B43: =IF('Items sous domaines Sciences '!G45=3,'Items sous domaines Sciences '!B45,0) -> 0 | C43: =IF('Items sous domaines Sciences '!G45=3,'Items sous domaines Sciences '!C45,0) -> 0 | D43: =IF('Items sous domaines Sciences '!G45=3,'Items sous domaines Sciences '!D45,0) -> 0 | E43: =IF('Items sous domaines Sciences '!G45=3,'Items sous domaines Sciences '!E45,0) -> 0
...

Sheet A3 CI Géné S5
A1: Objectifs d'apprentissage des sciences physiques
G2: Remédiation
A4: Notions à maîtriser en cycle ingénieur S5
G5: lien Unisciel ou livre scolaire
A7: ='A1 CPI S1'!A7 -> UE du DS | B7: ='A1 CPI S1'!B7 -> Domaine | C7: ='A1 CPI S1'!C7 -> Discipline | D7: ='A1 CPI S1'!D7 -> Chapitres | E7: ='A1 CPI S1'!E7 -> Thèmes | F7: Utilisation
A8: UE 5.3 Sciences physiques | B8: =IF('Items sous domaines Sciences '!G10=5,'Items sous domaines Sciences '!B10,0) -> 0 | C8: =IF('Items sous domaines Sciences '!G10=5,'Items sous domaines Sciences '!C10,0) -> 0 | D8: =IF('Items sous domaines Sciences '!G10=5,'Items sous domaines Sciences '!D10,0) -> 0 | E8: =IF('Items sous domaines Sciences '!G10=5,'Items sous domaines Sciences '!E10,0) -> 0 | F8: SAS (P2 Vieux-pont) et Projet Energ'in box | G8: https://uel.unisciel.fr/physique/meca/meca/co/meca.html https://uel.unisciel.fr/physique/continu/continu/co/continu.html
B9: =IF('Items sous domaines Sciences '!G11=5,'Items sous domaines Sciences '!B11,0) -> 0 | C9: =IF('Items sous domaines Sciences '!G11=5,'Items sous domaines Sciences '!C11,0) -> 0 | D9: =IF('Items sous domaines Sciences '!G11=5,'Items sous domaines Sciences '!D11,0) -> 0 | E9: =IF('Items sous domaines Sciences '!G11=5,'Items sous domaines Sciences '!E11,0) -> 0
B10: =IF('Items sous domaines Sciences '!G12=5,'Items sous domaines Sciences '!B12,0) -> 0 | C10: =IF('Items sous domaines Sciences '!G12=5,'Items sous domaines Sciences '!C12,0) -> 0 | D10: =IF('Items sous domaines Sciences '!G12=5,'Items sous domaines Sciences '!D12,0) -> 0 | E10: =IF('Items sous domaines Sciences '!G12=5,'Items sous domaines Sciences '!E12,0) -> 0
B11: =IF('Items sous domaines Sciences '!G13=5,'Items sous domaines Sciences '!B13,0) -> 0 | C11: =IF('Items sous domaines Sciences '!G13=5,'Items sous domaines Sciences '!C13,0) -> 0 | D11: =IF('Items sous domaines Sciences '!G13=5,'Items sous domaines Sciences '!D13,0) -> 0 | E11: =IF('Items sous domaines Sciences '!G13=5,'Items sous domaines Sciences '!E13,0) -> 0
B12: =IF('Items sous domaines Sciences '!G14=5,'Items sous domaines Sciences '!B14,0) -> 0 | C12: =IF('Items sous domaines Sciences '!G14=5,'Items sous domaines Sciences '!C14,0) -> 0 | D12: =IF('Items sous domaines Sciences '!G14=5,'Items sous domaines Sciences '!D14,0) -> 0 | E12: =IF('Items sous domaines Sciences '!G14=5,'Items sous domaines Sciences '!E14,0) -> 0
B13: =IF('Items sous domaines Sciences '!G15=5,'Items sous domaines Sciences '!B15,0) -> 0 | C13: =IF('Items sous domaines Sciences '!G15=5,'Items sous domaines Sciences '!C15,0) -> 0 | D13: =IF('Items sous domaines Sciences '!G15=5,'Items sous domaines Sciences '!D15,0) -> 0 | E13: =IF('Items sous domaines Sciences '!G15=5,'Items sous domaines Sciences '!E15,0) -> 0
B14: =IF('Items sous domaines Sciences '!G16=5,'Items sous domaines Sciences '!B16,0) -> 0 | C14: =IF('Items sous domaines Sciences '!G16=5,'Items sous domaines Sciences '!C16,0) -> 0 | D14: =IF('Items sous domaines Sciences '!G16=5,'Items sous domaines Sciences '!D16,0) -> 0 | E14: =IF('Items sous domaines Sciences '!G16=5,'Items sous domaines Sciences '!E16,0) -> 0
