Workbook

Sheet Objectifs Maths 2023-2024
B2: Objectifs d'apprentissage du tronc commun de la formation en mathématiques au sein de l'Ecole d'Ingénieurs CESI
B3: A - Fondamentaux en mathématiques (notions de prérequis) | C3: 1 | D3: Cycle préparatoire (CPI)
B4: A.1 Connaître les grandes notions d'algèbre, d'analyse, de géomètrie, de probabilité statiques
B5: A.2 Mobiliser les 6 compétences élémentaires dans des exercices d'application (Modéliser, Calculer, Représenter, Chercher, Communiquer, Raisonner)
B6: B - Calcul numérique et analytique
B7: B.1 Faire preuve d'autonomie, d'initiative dans la démarche de résolution d'un problème
B8: B.2 Savoir employer une démarche de résolution analytico-numérique (du modèle physique ou des hypothèses jusqu'à l'implémentation)
B9: B.3 Savoir lire, comprendre, concevoir des algorithmes (sans langage spécifique, en privilégiant le pseudo-code)
B10: B.4 Savoir analyser et interpréter un résultat, avoir un point de vue critique et l'exprimer
B11: C - Sciences des données | C11: 2 | D11: Cycle ingénieur (CI)
B12: C.1 Savoir gérer des jeux de données (choix des modèles discrets, continus ; des conditions)
B13: C.2 Savoir traiter les jeux de données, y compris de grand volume (décrire, visualiser, explorer, analyser, modéliser)
B14: C.3 Connaître les tests permettant une analyse décisionnelle
B15: D - Sciences de la modélisation
B16: D.1 Savoir identifier les outils utiles pour la résolution du problème
B17: D.2 Connaître, comprendre et savoir faire usage des outils de la modélisation numérique (MEF, VF, DF)
B18: D.3 Être capable d'analyse de critique des modèles, des résultats

Sheet Items sous domaines Maths 
A1: Objectifs d'apprentissage des Mathématiques | L1: Remédiation
A2: Propositions d'Items pour les Objectifs d'apprentissage | H2: nv | I2: nv rétention A4 | J2: nv rétention A2 | K2: A3 | L2: lien Unisciel ou livre scolaire
B7: Algèbre | D7: Arithmétique
B8: Algèbre | C8: Arithmétique | D8: Divisibilité | E8: Critères de divisibilité | H8: 1 | I8: 7 | K8: 5 | L8: https://uel.unisciel.fr/mathematiques/arithmetique/arithmetique/co/arithmetique.html | M8: lien1
B9: Algèbre | C9: Arithmétique | E9: Division euclidienne | F9: Algorithme d'Euclide. | H9: 1 | I9: 7 | K9: 5
B10: Algèbre | C10: Arithmétique | E10: Congruences | H10: 1 | I10: 7 | K10: 5 | L10: 22
B11: Algèbre | C11: Arithmétique | D11: Factorisation | E11: Nombres premiers, Crible d'Eratosthène | H11: 1 | I11: 7 | K11: 5
B12: Algèbre | C12: Arithmétique | E12: Lemme d'Euclide | H12: 1 | I12: 7 | K12: 5
B13: Algèbre | C13: Arithmétique | E13: Petit théorème de Fermat | H13: 1 | I13: 7 | K13: 5
B14: Algèbre | C14: Arithmétique | E14: Décomposition en facteurs premiers / Théorème fondamental de l'arithmétique | H14: 1 | I14: 7 | K14: 5
B15: Algèbre | C15: Arithmétique | D15: PGCD | E15: PGCD de 2 entiers, lien avec la décomposition en facteurs premiers | H15: 1 | I15: 7 | K15: 5
B16: Algèbre | C16: Arithmétique | E16: Théorème de Bezout | H16: 1 | I16: 7 | K16: 5
B17: Algèbre | C17: Arithmétique | E17: Nombres premiers entre eux, caractérisation via Bezout, Lemme de Gauss | H17: 1 | I17: 7 | K17: 5
B18: Algèbre | C18: Arithmétique | E18: PPCM | H18: 1 | I18: 7 | K18: 5
B19: Algèbre | C19: Arithmétique | D19: Équations dophantiennes | H19: 1 | I19: 7 | K19: 5
B20: Algèbre | C20: Arithmétique | D20: Chiffrage | E20: Chiffrement simple | F20: rot, César, Vigenère... | H20: 1 | I20: 7 | K20: 5
B21: Algèbre | C21: Arithmétique | E21: Chiffrement symétrique | F21: Verman | H21: 1 | I21: 7 | K21: 5
B22: Algèbre | C22: Arithmétique | E22: Division euclidienne de polynômes | F22: Lien avec les CRC | H22: 1 | I22: 7 | K22: 5
B23: Algèbre | C23: Arithmétique | E23: Chiffrement asymétrique | F23: RSA, PGP (hybride) | H23: 1 | I23: 7 | K23: 5
B24: Algèbre | C24: Arithmétique
B25: Algèbre | D25: Logique
B26: Algèbre | C26: Logique | D26: Logique et raisonnements | E26: Rudiments de logique | F26: Opérations : négation, conjonction, disjonction, implication, équivalence. | H26: 1 | K26: 5 | L26: https://uel.unisciel.fr/mathematiques/logique1/logique1/co/logique1.html
B27: Algèbre | C27: Logique | F27: Tables de vérité | H27: 1 | K27: 5
B28: Algèbre | C28: Logique | F28: Quantificateurs . | H28: 1 | K28: 5
B29: Algèbre | C29: Logique | F29: Négations | H29: 1 | K29: 5 | M29: lien Moodle
B30: Algèbre | C30: Logique | E30: Propriétés de N | F30: Définitions générales . | H30: 1 | K30: 5
B31: Algèbre | C31: Logique | F31: Parties de N . | H31: 1 | K31: 5
B32: Algèbre | C32: Logique | E32: Autres types de raisonnements | F32: Raisonnement par récurrence | H32: 1 | K32: 5
B33: Algèbre | C33: Logique | F33: Raisonnement par contraposition | H33: 1 | K33: 5
B34: Algèbre | C34: Logique | F34: Raisonnement par l’absurde | H34: 1 | K34: 5
B35: Algèbre | C35: Logique | D35: Logique booléenne | E35: Fonctions Booléennes | F35: Fonction NOT, NOR, AND, OR | H35: 1 | I35: 7 | K35: 5
B36: Algèbre | C36: Logique | F36: Tables de verité | H36: 1 | I36: 7 | K36: 5
B37: Algèbre | C37: Logique | E37: Représentations graphiques des fonctions booléennes | F37: Connaissance des symboles de représentation | H37: 1 | I37: 7 | K37: 5
B38: Algèbre | C38: Logique | F38: Utilisation dans la description des circuits logiques. | H38: 1 | I38: 7 | K38: 5
B39: Algèbre | D39: Les nombres complexes
B40: Algèbre | C40: Les nombres complexes | D40: Définition et écriture algébrique des nombres complexes | E40: Définition | F40: Connaître l'écriture algébrique, la partie réelle et imaginaire d'un nombre complexe | H40: 2 | I40: 7 | J40: 3 | K40: 5 | L40: https://uel.unisciel.fr/physique/outils_nancy/outils_nancy_ch04/co/apprendre_ch04.html | M40: lien1
B41: Algèbre | C41: Les nombres complexes | F41: Savoir faire des opérations sur les nombres complexes. | H41: 2 | I41: 7 | J41: 3 | K41: 5
B42: Algèbre | C42: Les nombres complexes | F42: Connaître et savoir calculer le conjugué d'un nombre complexe. Connaître les propriétés du conjugué et son utilité dans l'écriture des fractions complexes sous forme algébrique. | H42: 2 | I42: 7 | J42: 3 | K42: 5
B43: Algèbre | C43: Les nombres complexes | F43: Savoir associer un point du plan à un nombre complexe, affixe d’un point du plan, affixe d’un vecteur du plan (dentifier C au plan usuel muni d’un repère orthonormé direct) | H43: 2 | I43: 7 | J43: 3 | K43: 5
B44: Algèbre | C44: Les nombres complexes | E44: Module d’un nombre complexe | F44: Savoir calculer un module d'un nombre complexe. | H44: 2 | I44: 7 | J44: 3 | K44: 5
...

Sheet Remédiation
A1: Aide :
A2: Vous trouverez votre cursus dans les onglets
A3: Vous trouverez les éléments évaluables de votre dossier de synthèse avec les chapitres et thèmes sur lesquels vous serez interrogé
A4: Vos révisions sont donc ciblées sur la base de ce référentiel
A5: Pour les A1 et A3 vous pouvez renseigner vos scores et voir votre progression par rapport au positionnement
A8: 1) Donner le numéro de votre année | B8: 1
A10: 2) Insérer vos résultats (nombre de bonnes réponses) dans les cases blanches :
A12: =IF(OR($B$8=1,$B$8=3), "Positionnement", "Pas de Positionnement en A2-A4") -> Positionnement
A13: Compétences | B13: Calculer | C13: Raisonner | D13: Représenter | E13: Communiquer | F13: Chercher | G13: Modéliser | H13: % Réussite
A14: Chapitre/Capacités
A15: =IF(OR($B$8=1,$B$8=3),IF($B$8=1,Aide1!A4,Aide3!A4), ) -> Analyse : Suites | B15: 1 | C15: 1 | D15: 1 | E15: 1 | F15: 0 | G15: 1 | H15: =SUM(B15:G15)*100/5 -> 100
A16: =IF(OR($B$8=1,$B$8=3),IF($B$8=1,Aide1!A5,Aide3!A5), ) -> Analyse : Équations différentielles | B16: 0.5 | C16: 0 | D16: 0 | E16: 1 | F16: 0 | G16: 0 | H16: =SUM(B16:G16)*100/5 -> 30
A17: =IF(OR($B$8=1,$B$8=3),IF($B$8=1,Aide1!A6,Aide3!A6), ) -> Analyse : Intégration 1D | B17: 1 | C17: 1 | D17: 1 | E17: 0 | F17: 1 | G17: 1 | H17: =SUM(B17:G17)*100/5 -> 100
A18: =IF(OR($B$8=1,$B$8=3),IF($B$8=1,Aide1!A7,Aide3!A7), ) -> Analyse : Fonctions 1D | B18: 0 | C18: 1 | D18: 1 | H18: =SUM(B18:G18)*100/5 -> 40
A19: =IF(OR($B$8=1,$B$8=3),IF($B$8=1,Aide1!A8,Aide3!A8), ) -> Probabilités | B19: 1 | C19: 0 | D19: 1 | E19: 1 | F19: 1 | G19: 0 | H19: =SUM(B19:G19)*100/5 -> 80
A20: =IF(OR($B$8=1,$B$8=3),IF($B$8=1,Aide1!A9,Aide3!A9), ) -> Statistiques | B20: 1 | C20: 0 | D20: 1 | H20: =SUM(B20:G20)*100/5 -> 40
A21: =IF(OR($B$8=1,$B$8=3),IF($B$8=1,Aide1!A10,Aide3!A10), ) -> Algèbre : Nombres complexes | B21: 0 | C21: 0 | D21: 0 | F21: 0 | G21: 0 | H21: =SUM(B21:G21)*100/5 -> 0
A22: =IF(OR($B$8=1,$B$8=3),IF($B$8=1,Aide1!A11,Aide3!A11), ) -> Algèbre : Arithmétique | B22: 1 | C22: 0 | D22: 0 | E22: 1 | G22: 1 | H22: =SUM(B22:G22)*100/5 -> 60
A23: =IF(OR($B$8=1,$B$8=3),IF($B$8=1,Aide1!A12,Aide3!A12), ) -> Algèbre : Graphes et matrice | B23: 1 | C23: 1 | D23: 1 | E23: 0 | F23: 1 | G23: 1 | H23: =SUM(B23:G23)*100/5 -> 100
A24: =IF(OR($B$8=1,$B$8=3),IF($B$8=1,Aide1!A13,Aide3!A13), ) -> Géomètrie analytique et plane | B24: 1 | C24: 0 | D24: 1 | E24: 0.5 | G24: 1 | H24: =SUM(B24:G24)*100/5 -> 70
A25: =IF(OR($B$8=1,$B$8=3),IF($B$8=1,Aide1!A14,Aide3!A14), ) -> Algèbre : Polynômes | B25: 2 | C25: 0 | D25: 0 | E25: 1 | F25: 0 | H25: =SUM(B25:G25)*100/5 -> 60
A26: % Réussite | B26: =SUM(B15:B25)*100/17 -> 55.882353 | C26: =SUM(C15:C25)*100/8 -> 50 | D26: =SUM(D15:D25)*100/8 -> 87.5 | E26: =SUM(E15:E25)*100/8 -> 68.75 | F26: =SUM(F15:F25)*100/6 -> 50 | G26: =SUM(G15:G25)*100/8 -> 62.5
A29: Semestre impair
A30: Compétences | B30: Calculer | C30: Raisonner | D30: Représenter | E30: Communiquer | F30: Chercher | G30: Modéliser | H30: % Réussite
A31: Chapitre/Capacités
A32: =IF(OR($B$8=1,$B$8=3),IF($B$8=1,Aide1!A20,Aide3!A19),Aide2!A4) -> Géométrie | H32: =SUM(B32:G32)*100/(IF($B$8=1,Aide1!H20,Aide3!H19)) -> 0
A33: =IF(OR($B$8=1,$B$8=3),IF($B$8=1,Aide1!A21,Aide3!A20),Aide2!A5) -> Probabilités- Statistique | H33: =SUM(B33:G33)*100/(IF($B$8=1,Aide1!H21,Aide3!H20)) -> 0
A34: =IF(OR($B$8=1,$B$8=3),IF($B$8=1,Aide1!A22,Aide3!A21),Aide2!A6) -> Analyse : Suites et Séries | H34: =SUM(B34:G34)*100/(IF($B$8=1,Aide1!H22,Aide3!H21)) -> 0
A35: =IF(OR($B$8=1,$B$8=3),IF($B$8=1,Aide1!A23,Aide3!A22),Aide2!#REF!) -> Analyse : Primitives-Intégrations 0 | H35: =SUM(B35:G35)*100/(IF($B$8=1,Aide1!H23,Aide3!H22)) -> 0
A36: =IF(OR($B$8=1,$B$8=3),IF($B$8=1,Aide1!A24,Aide3!A23),Aide2!A7) -> Analyse : Interpolation, développement limité 0 | H36: =SUM(B36:G36)*100/(IF($B$8=1,Aide1!H24,Aide3!H23)) -> 0
A37: =IF(OR($B$8=1,$B$8=3),IF($B$8=1,Aide1!A25,Aide3!A24),Aide2!A8) -> Analyse : Equations différentielles 0 | H37: =SUM(B37:G37)*100/(IF($B$8=1,Aide1!H25,Aide3!H24)) -> 0
A38: =IF(OR($B$8=1,$B$8=3),IF($B$8=1,Aide1!A26,Aide3!A25),Aide2!A9) -> Algèbre : Arithmétique | H38: =SUM(B38:G38)*100/(IF($B$8=1,Aide1!H26,Aide3!H25)) -> 0
A39: =IF(OR($B$8=1,$B$8=3),IF($B$8=1,Aide1!A27,Aide3!A26),Aide2!A10) -> 0 | H39: =SUM(B39:G39)*100/(IF($B$8=1,Aide1!H27,Aide3!H26)) -> #DIV/0!
A40: =IF(OR($B$8=1,$B$8=3),IF($B$8=1,Aide1!A28,Aide3!A27),Aide2!A11) -> 0 | H40: =SUM(B40:G40)*100/(IF($B$8=1,Aide1!H28,Aide3!H27)) -> #DIV/0!
A41: =IF(OR($B$8=1,$B$8=3),IF($B$8=1,Aide1!A29,Aide3!A28),Aide2!A12) -> 0 | H41: =SUM(B41:G41)*100/(IF($B$8=1,Aide1!H29,Aide3!H28)) -> #DIV/0!
A42: % Réussite | B42: =SUM(B32:B41)*100/(IF($B$8=1,Aide1!B34,Aide3!B33)) -> 0 | C42: =SUM(C32:C41)*100/(IF($B$8=1,Aide1!C34,Aide3!C33)) -> 0 | D42: =SUM(D32:D41)*100/(IF($B$8=1,Aide1!D34,Aide3!D33)) -> 0 | E42: =SUM(E32:E41)*100/(IF($B$8=1,Aide1!E34,Aide3!E33)) -> 0 | F42: =SUM(F32:F41)*100/(IF($B$8=1,Aide1!F34,Aide3!F33)) -> 0 | G42: =SUM(G32:G41)*100/(IF($B$8=1,Aide1!G34,Aide3!G33)) -> 0
A47: Semestre pair
A48: Compétences | B48: Calculer | C48: Raisonner | D48: Représenter | E48: Communiquer | F48: Chercher | G48: Modéliser | H48: % Réussite
A49: Chapitre/Capacités
A50: =IF(OR($B$8=1,$B$8=3),IF($B$8=1,Aide1!A39,Aide3!A37),) -> Algèbre : Nombres complexes | H50: =SUM(B50:G50)*100/(IF($B$8=1,Aide1!H39,Aide3!H37)) -> 0
...

Sheet Aide1
A1: Le test de positionnement est constitué de :
A2: Compétences | B2: Calculer | C2: Raisonner | D2: Représenter | E2: Communiquer | F2: Chercher | G2: Modéliser
A3: Chapitre/Capacités
A4: Analyse : Suites | B4: 1 | C4: 1 | D4: 1 | E4: 1 | F4: 0 | G4: 1 | H4: =SUM(B4:G4) -> 5
A5: Analyse : Équations différentielles | B5: 2 | C5: 1 | D5: 0 | E5: 0 | F5: 1 | G5: 1 | H5: =SUM(B5:G5) -> 5
A6: Analyse : Intégration 1D | B6: 2 | C6: 0 | D6: 1 | E6: 1 | F6: 0 | G6: 1 | H6: =SUM(B6:G6) -> 5
A7: Analyse : Fonctions 1D | B7: 1 | C7: 1 | D7: 1 | E7: 1 | F7: 1 | G7: 0 | H7: =SUM(B7:G7) -> 5
A8: Probabilités | B8: 1 | C8: 0 | D8: 1 | E8: 1 | F8: 1 | G8: 1 | H8: =SUM(B8:G8) -> 5
A9: Statistiques | B9: 2 | C9: 1 | D9: 1 | E9: 1 | F9: 0 | G9: 0 | H9: =SUM(B9:G9) -> 5
A10: Algèbre : Nombres complexes | B10: 1 | C10: 1 | D10: 1 | E10: 0 | F10: 1 | G10: 1 | H10: =SUM(B10:G10) -> 5
A11: Algèbre : Arithmétique | B11: 2 | C11: 1 | D11: 0 | E11: 1 | F11: 0 | G11: 1 | H11: =SUM(B11:G11) -> 5
A12: Algèbre : Graphes et matrice | B12: 2 | C12: 0 | D12: 1 | E12: 0 | F12: 1 | G12: 1 | H12: =SUM(B12:G12) -> 5
A13: Géomètrie analytique et plane | B13: 1 | C13: 1 | D13: 1 | E13: 1 | F13: 0 | G13: 1 | H13: =SUM(B13:G13) -> 5
A14: Algèbre : Polynômes | B14: 2 | C14: 1 | D14: 0 | E14: 1 | F14: 1 | G14: 0 | H14: =SUM(B14:G14) -> 5
A15: nombre de questions | B15: =SUM(B4:B14) -> 17 | C15: =SUM(C4:C14) -> 8 | D15: =SUM(D4:D14) -> 8 | E15: =SUM(E4:E14) -> 8 | F15: =SUM(F4:F14) -> 6 | G15: =SUM(G4:G14) -> 8 | H15: =SUM(B15:G15) -> 55
A18: Compétences | B18: Calculer | C18: Raisonner | D18: Représenter | E18: Communiquer | F18: Chercher | G18: Modéliser
A19: Chapitre/Capacités
A20: Géométrie | B20: 1 | C20: 1 | D20: 1 | E20: 1 | F20: 1 | G20: 1 | H20: =SUM(B20:G20) -> 6
A21: Probabilités- Statistique | B21: 1 | C21: 1 | D21: 1 | E21: 1 | F21: 1 | G21: 1 | H21: =SUM(B21:G21) -> 6
A22: Analyse : Suites et Séries | B22: 1 | C22: 1 | D22: 1 | E22: 1 | F22: 1 | G22: 1 | H22: =SUM(B22:G22) -> 6
A23: Analyse : Primitives-Intégrations 0 | B23: 1 | C23: 1 | D23: 1 | E23: 1 | F23: 1 | G23: 1 | H23: =SUM(B23:G23) -> 6
A24: Analyse : Interpolation, développement limité 0 | B24: 1 | C24: 1 | D24: 1 | E24: 1 | F24: 1 | G24: 1 | H24: =SUM(B24:G24) -> 6
A25: Analyse : Equations différentielles 0 | B25: 1 | C25: 1 | D25: 1 | E25: 1 | F25: 1 | G25: 1 | H25: =SUM(B25:G25) -> 6
A26: Algèbre : Arithmétique | B26: 1 | C26: 1 | D26: 1 | E26: 1 | F26: 1 | G26: 1 | H26: =SUM(B26:G26) -> 6
H27: =SUM(B27:G27) -> 0
H28: =SUM(B28:G28) -> 0
H29: =SUM(B29:G29) -> 0
H30: =SUM(B30:G30) -> 0
H31: =SUM(B31:G31) -> 0
H32: =SUM(B32:G32) -> 0
H33: =SUM(B33:G33) -> 0
A34: nombre de questions | B34: =SUM(B20:B33) -> 7 | C34: =SUM(C20:C33) -> 7 | D34: =SUM(D20:D33) -> 7 | E34: =SUM(E20:E33) -> 7 | F34: =SUM(F20:F33) -> 7 | G34: =SUM(G20:G33) -> 7 | H34: =SUM(B34:G34) -> 42
A37: Compétences | B37: Calculer | C37: Raisonner | D37: Représenter | E37: Communiquer | F37: Chercher | G37: Modéliser
A38: Chapitre/Capacités
A39: Algèbre : Nombres complexes | B39: 1 | C39: 1 | D39: 1 | E39: 1 | F39: 1 | G39: 1 | H39: =SUM(B39:G39) -> 6
A40: Analyse : Etude 1D | B40: 1 | C40: 1 | D40: 1 | E40: 1 | F40: 1 | G40: 1 | H40: =SUM(B40:G40) -> 6
A41: Analyse : fonctions de plx variables | B41: 1 | C41: 1 | D41: 1 | E41: 1 | F41: 1 | G41: 1 | H41: =SUM(B44:G44) -> 6
A42: Graphes | B42: 1 | C42: 1 | D42: 1 | E42: 1 | F42: 1 | G42: 1 | H42: =SUM(B42:G42) -> 6
A43: Matrices et systèmes | B43: 1 | C43: 1 | D43: 1 | E43: 1 | F43: 1 | G43: 1 | H43: =SUM(B43:G43) -> 6
A44: Probabilités | B44: 1 | C44: 1 | D44: 1 | E44: 1 | F44: 1 | G44: 1 | H44: =SUM(B44:G44) -> 6
...

Sheet Aide2
A2: Compétences | B2: Calculer | C2: Raisonner | D2: Représenter | E2: Communiquer | F2: Chercher | G2: Modéliser
A3: Chapitre/Capacités
A4: QCM : Analyse : Etude de plusieurs variables, suites et série | B4: 6
A5: QCM : Géométrie | B5: 6
A6: QCM : Algèbre : nombres complexes, matrices et systèmes | B6: 6
A7: Epreuve rédactionnelle - Etude de fonctions 1D | B7: 6
A8: Epreuve rédactionnelle :Maths spé G/BTP : fonctions de plusieurs variables // Info/S3E Complexité Algo | B8: 6
A9: Epreuve rédactionnelle : Statistique et probabilités | B9: 6
A10: Epreuve rédactionnelle : Equations différentielles | B10: 6

Sheet Aide3
A1: Le test de positionnement est constitué de :
A2: Compétences | B2: Calculer | C2: Raisonner | D2: Représenter | E2: Communiquer | F2: Chercher | G2: Modéliser
A3: Chapitre/Capacités
A4: Analyse : Suites et Séries numériques | B4: 1 | C4: 1 | D4: 1 | E4: 1 | F4: 0 | G4: 1 | H4: =SUM(B4:G4) -> 5
A5: Analyse : Équations différentielles | B5: 2 | C5: 1 | D5: 0 | E5: 0 | F5: 1 | G5: 1 | H5: =SUM(B5:G5) -> 5
A6: Analyse : Intégration 1-2-3 D | B6: 2 | C6: 0 | D6: 1 | E6: 1 | F6: 0 | G6: 1 | H6: =SUM(B6:G6) -> 5
A7: Analyse : Fonctions 1-2-3 D | B7: 1 | C7: 1 | D7: 1 | E7: 1 | F7: 1 | G7: 0 | H7: =SUM(B7:G7) -> 5
A8: Probabilités | B8: 1 | C8: 0 | D8: 1 | E8: 1 | F8: 1 | G8: 1 | H8: =SUM(B8:G8) -> 5
A9: Statistiques | B9: 2 | C9: 1 | D9: 1 | E9: 1 | F9: 0 | G9: 0 | H9: =SUM(B9:G9) -> 5
A10: Algèbre : Nombres complexes | B10: 1 | C10: 1 | D10: 1 | E10: 0 | F10: 1 | G10: 1 | H10: =SUM(B10:G10) -> 5
A11: Algèbre : Arithmétique | B11: 2 | C11: 1 | D11: 0 | E11: 1 | F11: 0 | G11: 1 | H11: =SUM(B11:G11) -> 5
A12: Algèbre : Graphes et matrice | B12: 2 | C12: 0 | D12: 1 | E12: 0 | F12: 1 | G12: 1 | H12: =SUM(B12:G12) -> 5
A13: Géomètrie analytique et plane | B13: 1 | C13: 1 | D13: 1 | E13: 1 | F13: 0 | G13: 1 | H13: =SUM(B13:G13) -> 5
A14: Algèbre : Polynômes | B14: 2 | C14: 1 | D14: 0 | E14: 1 | F14: 1 | G14: 0 | H14: =SUM(B14:G14) -> 5
A15: nombre de questions | B15: =SUM(B4:B14) -> 17 | C15: =SUM(C4:C14) -> 8 | D15: =SUM(D4:D14) -> 8 | E15: =SUM(E4:E14) -> 8 | F15: =SUM(F4:F14) -> 6 | G15: =SUM(G4:G14) -> 8 | H15: =SUM(H4:H14) -> 55
A17: Compétences | B17: Calculer | C17: Raisonner | D17: Représenter | E17: Communiquer | F17: Chercher | G17: Modéliser
A18: Chapitre/Capacités
A19: QCM : Analyse : Equations différentielles 1 | B19: 2 | C19: 1 | D19: 0 | E19: 1 | F19: 1 | G19: 1 | H19: =SUM(B19:G19) -> 6
A20: QCM : Analyse : fonctions multivariées, opérateurs et développements limités | B20: 2 | C20: 1 | D20: 1 | E20: 0 | F20: 1 | G20: 1 | H20: =SUM(B20:G20) -> 6
A21: QCM : Probabilités continues et discrètes | B21: 2 | C21: 1 | D21: 1 | E21: 1 | F21: 1 | G21: 1 | H21: =SUM(B21:G21) -> 7
A22: QCM : Statistiques univariés et bivariés | B22: 2 | C22: 1 | D22: 1 | E22: 1 | F22: 1 | G22: 1 | H22: =SUM(B22:G22) -> 7
A23: QCM : Géomètrie | B23: 2 | C23: 1 | D23: 1 | E23: 1 | F23: 1 | G23: 1 | H23: =SUM(B23:G23) -> 7
A24: QCM : Analyse : suites, série 1 | B24: 2 | C24: 1 | D24: 1 | E24: 1 | F24: 1 | G24: 1 | H24: =SUM(B24:G24) -> 7
A25: QCM : Algèbre : Nombres complexes | B25: 2 | C25: 0 | D25: 1 | E25: 1 | F25: 0 | G25: 1 | H25: =SUM(B25:G25) -> 5
A26: QCM : Algèbre : Arithmétique | B26: 2 | C26: 0 | D26: 0 | E26: 1 | F26: 1 | G26: 1 | H26: =SUM(B26:G26) -> 5
A27: QCM : Algèbre : Matrice et système | B27: 2 | C27: 0 | D27: 1 | E27: 1 | F27: 1 | G27: 0 | H27: =SUM(B27:G27) -> 5
A28: QCM : Analyse : fonctiosn, developpement limités | B28: 2 | C28: 1 | D28: 0 | E28: 0 | F28: 1 | G28: 1 | H28: =SUM(B28:G28) -> 5
H29: =SUM(B29:G29) -> 0
H30: =SUM(B30:G30) -> 0
H31: =SUM(B31:G31) -> 0
H32: =SUM(B32:G32) -> 0
A33: nombre de questions | B33: =SUM(B19:B32) -> 20 | C33: =SUM(C19:C32) -> 7 | D33: =SUM(D19:D32) -> 7 | E33: =SUM(E19:E32) -> 8 | F33: =SUM(F19:F32) -> 9 | G33: =SUM(G19:G32) -> 9 | H33: =SUM(H27:H32) -> 10
A35: Compétences | B35: Calculer | C35: Raisonner | D35: Représenter | E35: Communiquer | F35: Chercher | G35: Modéliser
A36: Chapitre/Capacités
A37: QCM : Géométrie | B37: 1 | C37: 1 | D37: 1 | E37: 1 | F37: 1 | G37: 1 | H37: =SUM(B37:G37) -> 6
A38: QCM : Analyse : suites, série 1 | B38: 1 | C38: 1 | D38: 1 | E38: 1 | F38: 1 | G38: 1 | H38: =SUM(B38:G38) -> 6
A39: QCM : Algèbre : Nombres complexes | B39: 1 | C39: 1 | D39: 1 | E39: 1 | F39: 1 | G39: 1 | H39: =SUM(B39:G39) -> 6
A40: QCM : Analyse : Etude nD | B40: 1 | C40: 1 | D40: 1 | E40: 1 | F40: 1 | G40: 1 | H40: =SUM(B40:G40) -> 6
A41: QCM : Algèbre : Matrice et système | B41: 1 | C41: 1 | D41: 1 | E41: 1 | F41: 1 | G41: 1 | H41: =SUM(B41:G41) -> 6
A42: Rédactionnel : Démarche : Transformées de Laplace et Equa Diff, fonctions NV 1 et 2 | B42: 1 | C42: 1 | D42: 1 | E42: 1 | F42: 1 | G42: 1 | H42: =SUM(B42:G42) -> 6
...

Sheet A1 CPI S1
A1: Objectifs d'apprentissage des Mathématiques | H1: Remédiation
A2: Notions à maîtriser en CPI A1 S1 | H2: lien Unisciel ou livre scolaire
A3: EE du DS | B3: Domaine | C3: Discipline | D3: Chapitres | E3: Thèmes | F3: Détail des chapitres | G3: Utilisation
A4: Algèbre : Arithmétique | B4: =IF('Items sous domaines Maths '!H8=1,'Items sous domaines Maths '!B8,0) -> Algèbre | C4: =IF('Items sous domaines Maths '!H8=1,'Items sous domaines Maths '!C8) -> Arithmétique | D4: =IF('Items sous domaines Maths '!H8=1,'Items sous domaines Maths '!D8,0) -> Divisibilité | E4: =IF('Items sous domaines Maths '!H8=1,'Items sous domaines Maths '!E8,0) -> Critères de divisibilité | F4: =IF('Items sous domaines Maths '!H8=1,'Items sous domaines Maths '!F8,0) -> 0 | G4: ETS | H4: https://uel.unisciel.fr/mathematiques/arithmetique/arithmetique/co/arithmetique.html | I4: lien1
B5: =IF('Items sous domaines Maths '!H9=1,'Items sous domaines Maths '!B9,0) -> Algèbre | C5: =IF('Items sous domaines Maths '!H9=1,'Items sous domaines Maths '!C9,0) -> Arithmétique | D5: =IF('Items sous domaines Maths '!H9=1,'Items sous domaines Maths '!D9,0) -> 0 | E5: =IF('Items sous domaines Maths '!H9=1,'Items sous domaines Maths '!E9,0) -> Division euclidienne | F5: =IF('Items sous domaines Maths '!H9=1,'Items sous domaines Maths '!F9,0) -> Algorithme d'Euclide.
B6: =IF('Items sous domaines Maths '!H10=1,'Items sous domaines Maths '!B10,0) -> Algèbre | C6: =IF('Items sous domaines Maths '!H10=1,'Items sous domaines Maths '!C10,0) -> Arithmétique | D6: =IF('Items sous domaines Maths '!H10=1,'Items sous domaines Maths '!D10,0) -> 0 | E6: =IF('Items sous domaines Maths '!H10=1,'Items sous domaines Maths '!E10,0) -> Congruences | F6: =IF('Items sous domaines Maths '!H10=1,'Items sous domaines Maths '!F10,0) -> 0
B7: =IF('Items sous domaines Maths '!H11=1,'Items sous domaines Maths '!B11,0) -> Algèbre | C7: =IF('Items sous domaines Maths '!H11=1,'Items sous domaines Maths '!C11,0) -> Arithmétique | D7: =IF('Items sous domaines Maths '!H11=1,'Items sous domaines Maths '!D11,0) -> Factorisation | E7: =IF('Items sous domaines Maths '!H11=1,'Items sous domaines Maths '!E11,0) -> Nombres premiers, Crible d'Eratosthène | F7: =IF('Items sous domaines Maths '!H11=1,'Items sous domaines Maths '!F11,0) -> 0
B8: =IF('Items sous domaines Maths '!H12=1,'Items sous domaines Maths '!B12,0) -> Algèbre | C8: =IF('Items sous domaines Maths '!H12=1,'Items sous domaines Maths '!C12,0) -> Arithmétique | D8: =IF('Items sous domaines Maths '!H12=1,'Items sous domaines Maths '!D12,0) -> 0 | E8: =IF('Items sous domaines Maths '!H12=1,'Items sous domaines Maths '!E12,0) -> Lemme d'Euclide | F8: =IF('Items sous domaines Maths '!H12=1,'Items sous domaines Maths '!F12,0) -> 0
B9: =IF('Items sous domaines Maths '!H13=1,'Items sous domaines Maths '!B13,0) -> Algèbre | C9: =IF('Items sous domaines Maths '!H13=1,'Items sous domaines Maths '!C13,0) -> Arithmétique | D9: =IF('Items sous domaines Maths '!H13=1,'Items sous domaines Maths '!D13,0) -> 0 | E9: =IF('Items sous domaines Maths '!H13=1,'Items sous domaines Maths '!E13,0) -> Petit théorème de Fermat | F9: =IF('Items sous domaines Maths '!H13=1,'Items sous domaines Maths '!F13,0) -> 0
B10: =IF('Items sous domaines Maths '!H14=1,'Items sous domaines Maths '!B14,0) -> Algèbre | C10: =IF('Items sous domaines Maths '!H14=1,'Items sous domaines Maths '!C14,0) -> Arithmétique | D10: =IF('Items sous domaines Maths '!H14=1,'Items sous domaines Maths '!D14,0) -> 0 | E10: =IF('Items sous domaines Maths '!H14=1,'Items sous domaines Maths '!E14,0) -> Décomposition en facteurs premiers / Théorème fondamental de l'arithmétique | F10: =IF('Items sous domaines Maths '!H14=1,'Items sous domaines Maths '!F14,0) -> 0
B11: =IF('Items sous domaines Maths '!H15=1,'Items sous domaines Maths '!B15,0) -> Algèbre | C11: =IF('Items sous domaines Maths '!H15=1,'Items sous domaines Maths '!C15,0) -> Arithmétique | D11: =IF('Items sous domaines Maths '!H15=1,'Items sous domaines Maths '!D15,0) -> PGCD | E11: =IF('Items sous domaines Maths '!H15=1,'Items sous domaines Maths '!E15,0) -> PGCD de 2 entiers, lien avec la décomposition en facteurs premiers | F11: =IF('Items sous domaines Maths '!H15=1,'Items sous domaines Maths '!F15,0) -> 0
B12: =IF('Items sous domaines Maths '!H16=1,'Items sous domaines Maths '!B16,0) -> Algèbre | C12: =IF('Items sous domaines Maths '!H16=1,'Items sous domaines Maths '!C16,0) -> Arithmétique | D12: =IF('Items sous domaines Maths '!H16=1,'Items sous domaines Maths '!D16,0) -> 0 | E12: =IF('Items sous domaines Maths '!H16=1,'Items sous domaines Maths '!E16,0) -> Théorème de Bezout | F12: =IF('Items sous domaines Maths '!H16=1,'Items sous domaines Maths '!F16,0) -> 0
B13: =IF('Items sous domaines Maths '!H17=1,'Items sous domaines Maths '!B17,0) -> Algèbre | C13: =IF('Items sous domaines Maths '!H17=1,'Items sous domaines Maths '!C17,0) -> Arithmétique | D13: =IF('Items sous domaines Maths '!H17=1,'Items sous domaines Maths '!D17,0) -> 0 | E13: =IF('Items sous domaines Maths '!H17=1,'Items sous domaines Maths '!E17,0) -> Nombres premiers entre eux, caractérisation via Bezout, Lemme de Gauss | F13: =IF('Items sous domaines Maths '!H17=1,'Items sous domaines Maths '!F17,0) -> 0
B14: =IF('Items sous domaines Maths '!H18=1,'Items sous domaines Maths '!B18,0) -> Algèbre | C14: =IF('Items sous domaines Maths '!H18=1,'Items sous domaines Maths '!C18,0) -> Arithmétique | D14: =IF('Items sous domaines Maths '!H18=1,'Items sous domaines Maths '!D18,0) -> 0 | E14: =IF('Items sous domaines Maths '!H18=1,'Items sous domaines Maths '!E18,0) -> PPCM | F14: =IF('Items sous domaines Maths '!H18=1,'Items sous domaines Maths '!F18,0) -> 0
B15: =IF('Items sous domaines Maths '!H19=1,'Items sous domaines Maths '!B19,0) -> Algèbre | C15: =IF('Items sous domaines Maths '!H19=1,'Items sous domaines Maths '!C19,0) -> Arithmétique | D15: =IF('Items sous domaines Maths '!H19=1,'Items sous domaines Maths '!D19,0) -> Équations dophantiennes | E15: =IF('Items sous domaines Maths '!H19=1,'Items sous domaines Maths '!E19,0) -> 0 | F15: =IF('Items sous domaines Maths '!H19=1,'Items sous domaines Maths '!F19,0) -> 0
B16: =IF('Items sous domaines Maths '!H20=1,'Items sous domaines Maths '!B20,0) -> Algèbre | C16: =IF('Items sous domaines Maths '!H20=1,'Items sous domaines Maths '!C20,0) -> Arithmétique | D16: =IF('Items sous domaines Maths '!H20=1,'Items sous domaines Maths '!D20,0) -> Chiffrage | E16: =IF('Items sous domaines Maths '!H20=1,'Items sous domaines Maths '!E20,0) -> Chiffrement simple | F16: =IF('Items sous domaines Maths '!H20=1,'Items sous domaines Maths '!F20,0) -> rot, César, Vigenère...
... B19: =IF('Items sous domaines Maths '!H23=1,'Items sous domaines Maths '!B23,0) -> Algèbre | C19: =IF('Items sous domaines Maths '!H23=1,'Items sous domaines Maths '!C23,0) -> Arithmétique | D19: =IF('Items sous domaines Maths '!H23=1,'Items sous domaines Maths '!D23,0) -> 0 | E19: =IF('Items sous domaines Maths '!H23=1,'Items sous domaines Maths '!E23,0) -> Chiffrement asymétrique | F19: =IF('Items sous domaines Maths '!H23=1,'Items sous domaines Maths '!F23,0) -> RSA, PGP (hybride)
B20: =IF('Items sous domaines Maths '!H24=1,'Items sous domaines Maths '!B24,0) -> 0 | C20: =IF('Items sous domaines Maths '!H24=1,'Items sous domaines Maths '!C24,0) -> 0 | D20: =IF('Items sous domaines Maths '!H24=1,'Items sous domaines Maths '!D24,0) -> 0 | E20: =IF('Items sous domaines Maths '!H24=1,'Items sous domaines Maths '!E24,0) -> 0 | F20: =IF('Items sous domaines Maths '!H24=1,'Items sous domaines Maths '!F24,0) -> 0 | G20: =IF('Items sous domaines Maths '!H24=1,'Items sous domaines Maths '!G24,0) -> 0
B21: =IF('Items sous domaines Maths '!H25=1,'Items sous domaines Maths '!B25,0) -> 0 | C21: =IF('Items sous domaines Maths '!H25=1,'Items sous domaines Maths '!C25,0) -> 0 | D21: =IF('Items sous domaines Maths '!H25=1,'Items sous domaines Maths '!D25,0) -> 0 | E21: =IF('Items sous domaines Maths '!H25=1,'Items sous domaines Maths '!E25,0) -> 0 | F21: =IF('Items sous domaines Maths '!H25=1,'Items sous domaines Maths '!F25,0) -> 0 | G21: =IF('Items sous domaines Maths '!H25=1,'Items sous domaines Maths '!G25,0) -> 0
A22: Algèbre de Boole (hors TOMIC) | B22: =IF('Items sous domaines Maths '!H26=1,'Items sous domaines Maths '!B26,0) -> Algèbre | C22: =IF('Items sous domaines Maths '!H26=1,'Items sous domaines Maths '!C26,0) -> Logique | D22: =IF('Items sous domaines Maths '!H26=1,'Items sous domaines Maths '!D26,0) -> Logique et raisonnements | E22: =IF('Items sous domaines Maths '!H26=1,'Items sous domaines Maths '!E26,0) -> Rudiments de logique | F22: =IF('Items sous domaines Maths '!H26=1,'Items sous domaines Maths '!F26,0) -> Opérations : négation, conjonction, disjonction, implication, équivalence. | G22: Projet Strongbox-Electronique | H22: https://uel.unisciel.fr/mathematiques/logique1/logique1/co/logique1.html
B23: =IF('Items sous domaines Maths '!H27=1,'Items sous domaines Maths '!B27,0) -> Algèbre | C23: =IF('Items sous domaines Maths '!H27=1,'Items sous domaines Maths '!C27,0) -> Logique | D23: =IF('Items sous domaines Maths '!H27=1,'Items sous domaines Maths '!D27,0) -> 0 | E23: =IF('Items sous domaines Maths '!H27=1,'Items sous domaines Maths '!E27,0) -> 0 | F23: =IF('Items sous domaines Maths '!H27=1,'Items sous domaines Maths '!F27,0) -> Tables de vérité
B24: =IF('Items sous domaines Maths '!H28=1,'Items sous domaines Maths '!B28,0) -> Algèbre | C24: =IF('Items sous domaines Maths '!H28=1,'Items sous domaines Maths '!C28,0) -> Logique | D24: =IF('Items sous domaines Maths '!H28=1,'Items sous domaines Maths '!D28,0) -> 0 | E24: =IF('Items sous domaines Maths '!H28=1,'Items sous domaines Maths '!E28,0) -> 0 | F24: =IF('Items sous domaines Maths '!H28=1,'Items sous domaines Maths '!F28,0) -> Quantificateurs .
B25: =IF('Items sous domaines Maths '!H29=1,'Items sous domaines Maths '!B29,0) -> Algèbre | C25: =IF('Items sous domaines Maths '!H29=1,'Items sous domaines Maths '!C29,0) -> Logique | D25: =IF('Items sous domaines Maths '!H29=1,'Items sous domaines Maths '!D29,0) -> 0 | E25: =IF('Items sous domaines Maths '!H29=1,'Items sous domaines Maths '!E29,0) -> 0 | F25: =IF('Items sous domaines Maths '!H29=1,'Items sous domaines Maths '!F29,0) -> Négations | I25: lien Moodle
B26: =IF('Items sous domaines Maths '!H30=1,'Items sous domaines Maths '!B30,0) -> Algèbre | C26: =IF('Items sous domaines Maths '!H30=1,'Items sous domaines Maths '!C30,0) -> Logique | D26: =IF('Items sous domaines Maths '!H30=1,'Items sous domaines Maths '!D30,0) -> 0 | E26: =IF('Items sous domaines Maths '!H30=1,'Items sous domaines Maths '!E30,0) -> Propriétés de N | F26: =IF('Items sous domaines Maths '!H30=1,'Items sous domaines Maths '!F30,0) -> Définitions générales .
B27: =IF('Items sous domaines Maths '!H31=1,'Items sous domaines Maths '!B31,0) -> Algèbre | C27: =IF('Items sous domaines Maths '!H31=1,'Items sous domaines Maths '!C31,0) -> Logique | D27: =IF('Items sous domaines Maths '!H31=1,'Items sous domaines Maths '!D31,0) -> 0 | E27: =IF('Items sous domaines Maths '!H31=1,'Items sous domaines Maths '!E31,0) -> 0 | F27: =IF('Items sous domaines Maths '!H31=1,'Items sous domaines Maths '!F31,0) -> Parties de N .
B28: =IF('Items sous domaines Maths '!H32=1,'Items sous domaines Maths '!B32,0) -> Algèbre | C28: =IF('Items sous domaines Maths '!H32=1,'Items sous domaines Maths '!C32,0) -> Logique | D28: =IF('Items sous domaines Maths '!H32=1,'Items sous domaines Maths '!D32,0) -> 0 | E28: =IF('Items sous domaines Maths '!H32=1,'Items sous domaines Maths '!E32,0) -> Autres types de raisonnements | F28: =IF('Items sous domaines Maths '!H32=1,'Items sous domaines Maths '!F32,0) -> Raisonnement par récurrence
B29: =IF('Items sous domaines Maths '!H33=1,'Items sous domaines Maths '!B33,0) -> Algèbre | C29: =IF('Items sous domaines Maths '!H33=1,'Items sous domaines Maths '!C33,0) -> Logique | D29: =IF('Items sous domaines Maths '!H33=1,'Items sous domaines Maths '!D33,0) -> 0 | E29: =IF('Items sous domaines Maths '!H33=1,'Items sous domaines Maths '!E33,0) -> 0 | F29: =IF('Items sous domaines Maths '!H33=1,'Items sous domaines Maths '!F33,0) -> Raisonnement par contraposition
B30: =IF('Items sous domaines Maths '!H34=1,'Items sous domaines Maths '!B34,0) -> Algèbre | C30: =IF('Items sous domaines Maths '!H34=1,'Items sous domaines Maths '!C34,0) -> Logique | D30: =IF('Items sous domaines Maths '!H34=1,'Items sous domaines Maths '!D34,0) -> 0 | E30: =IF('Items sous domaines Maths '!H34=1,'Items sous domaines Maths '!E34,0) -> 0 | F30: =IF('Items sous domaines Maths '!H34=1,'Items sous domaines Maths '!F34,0) -> Raisonnement par l’absurde
B31: =IF('Items sous domaines Maths '!H35=1,'Items sous domaines Maths '!B35,0) -> Algèbre | C31: =IF('Items sous domaines Maths '!H35=1,'Items sous domaines Maths '!C35,0) -> Logique | D31: =IF('Items sous domaines Maths '!H35=1,'Items sous domaines Maths '!D35,0) -> Logique booléenne | E31: =IF('Items sous domaines Maths '!H35=1,'Items sous domaines Maths '!E35,0) -> Fonctions Booléennes | F31: =IF('Items sous domaines Maths '!H35=1,'Items sous domaines Maths '!F35,0) -> Fonction NOT, NOR, AND, OR
B32: =IF('Items sous domaines Maths '!H36=1,'Items sous domaines Maths '!B36,0) -> Algèbre | C32: =IF('Items sous domaines Maths '!H36=1,'Items sous domaines Maths '!C36,0) -> Logique | D32: =IF('Items sous domaines Maths '!H36=1,'Items sous domaines Maths '!D36,0) -> 0 | E32: =IF('Items sous domaines Maths '!H36=1,'Items sous domaines Maths '!E36,0) -> 0 | F32: =IF('Items sous domaines Maths '!H36=1,'Items sous domaines Maths '!F36,0) -> Tables de verité
B33: =IF('Items sous domaines Maths '!H37=1,'Items sous domaines Maths '!B37,0) -> Algèbre | C33: =IF('Items sous domaines Maths '!H37=1,'Items sous domaines Maths '!C37,0) -> Logique | D33: =IF('Items sous domaines Maths '!H37=1,'Items sous domaines Maths '!D37,0) -> 0 | E33: =IF('Items sous domaines Maths '!H37=1,'Items sous domaines Maths '!E37,0) -> Représentations graphiques des fonctions booléennes | F33: =IF('Items sous domaines Maths '!H37=1,'Items sous domaines Maths '!F37,0) -> Connaissance des symboles de représentation
B34: =IF('Items sous domaines Maths '!H38=1,'Items sous domaines Maths '!B38,0) -> Algèbre | C34: =IF('Items sous domaines Maths '!H38=1,'Items sous domaines Maths '!C38,0) -> Logique | D34: =IF('Items sous domaines Maths '!H38=1,'Items sous domaines Maths '!D38,0) -> 0 | E34: =IF('Items sous domaines Maths '!H38=1,'Items sous domaines Maths '!E38,0) -> 0 | F34: =IF('Items sous domaines Maths '!H38=1,'Items sous domaines Maths '!F38,0) -> Utilisation dans la description des circuits logiques.
B35: =IF('Items sous domaines Maths '!H39=1,'Items sous domaines Maths '!B39,0) -> 0 | C35: =IF('Items sous domaines Maths '!H39=1,'Items sous domaines Maths '!C39,0) -> 0 | D35: =IF('Items sous domaines Maths '!H39=1,'Items sous domaines Maths '!D39,0) -> 0 | E35: =IF('Items sous domaines Maths '!H39=1,'Items sous domaines Maths '!E39,0) -> 0 | F35: =IF('Items sous domaines Maths '!H39=1,'Items sous domaines Maths '!F39,0) -> 0 | G35: =IF('Items sous domaines Maths '!H39=1,'Items sous domaines Maths '!G39,0) -> 0
B36: =IF('Items sous domaines Maths '!H40=1,'Items sous domaines Maths '!B40,0) -> 0 | C36: =IF('Items sous domaines Maths '!H40=1,'Items sous domaines Maths '!C40,0) -> 0 | D36: =IF('Items sous domaines Maths '!H40=1,'Items sous domaines Maths '!D40,0) -> 0 | E36: =IF('Items sous domaines Maths '!H40=1,'Items sous domaines Maths '!E40,0) -> 0 | F36: =IF('Items sous domaines Maths '!H40=1,'Items sous domaines Maths '!F40,0) -> 0 | G36: Projet Strongbox-Electronique et ETS | H36: https://uel.unisciel.fr/physique/outils_nancy/outils_nancy_ch04/co/apprendre_ch04.html | I36: lien1
B37: =IF('Items sous domaines Maths '!H41=1,'Items sous domaines Maths '!B41,0) -> 0 | C37: =IF('Items sous domaines Maths '!H41=1,'Items sous domaines Maths '!C41,0) -> 0 | D37: =IF('Items sous domaines Maths '!H41=1,'Items sous domaines Maths '!D41,0) -> 0 | E37: =IF('Items sous domaines Maths '!H41=1,'Items sous domaines Maths '!E41,0) -> 0 | F37: =IF('Items sous domaines Maths '!H41=1,'Items sous domaines Maths '!F41,0) -> 0
B38: =IF('Items sous domaines Maths '!H42=1,'Items sous domaines Maths '!B42,0) -> 0 | C38: =IF('Items sous domaines Maths '!H42=1,'Items sous domaines Maths '!C42,0) -> 0 | D38: =IF('Items sous domaines Maths '!H42=1,'Items sous domaines Maths '!D42,0) -> 0 | E38: =IF('Items sous domaines Maths '!H42=1,'Items sous domaines Maths '!E42,0) -> 0 | F38: =IF('Items sous domaines Maths '!H42=1,'Items sous domaines Maths '!F42,0) -> 0
B39: =IF('Items sous domaines Maths '!H43=1,'Items sous domaines Maths '!B43,0) -> 0 | C39: =IF('Items sous domaines Maths '!H43=1,'Items sous domaines Maths '!C43,0) -> 0 | D39: =IF('Items sous domaines Maths '!H43=1,'Items sous domaines Maths '!D43,0) -> 0 | E39: =IF('Items sous domaines Maths '!H43=1,'Items sous domaines Maths '!E43,0) -> 0 | F39: =IF('Items sous domaines Maths '!H43=1,'Items sous domaines Maths '!F43,0) -> 0
B40: =IF('Items sous domaines Maths '!H44=1,'Items sous domaines Maths '!B44,0) -> 0 | C40: =IF('Items sous domaines Maths '!H44=1,'Items sous domaines Maths '!C44,0) -> 0 | D40: =IF('Items sous domaines Maths '!H44=1,'Items sous domaines Maths '!D44,0) -> 0 | E40: =IF('Items sous domaines Maths '!H44=1,'Items sous domaines Maths '!E44,0) -> 0 | F40: =IF('Items sous domaines Maths '!H44=1,'Items sous domaines Maths '!F44,0) -> 0
B41: =IF('Items sous domaines Maths '!H45=1,'Items sous domaines Maths '!B45,0) -> 0 | C41: =IF('Items sous domaines Maths '!H45=1,'Items sous domaines Maths '!C45,0) -> 0 | D41: =IF('Items sous domaines Maths '!H45=1,'Items sous domaines Maths '!D45,0) -> 0 | E41: =IF('Items sous domaines Maths '!H45=1,'Items sous domaines Maths '!E45,0) -> 0 | F41: =IF('Items sous domaines Maths '!H45=1,'Items sous domaines Maths '!F45,0) -> 0
B42: =IF('Items sous domaines Maths '!H46=1,'Items sous domaines Maths '!B46,0) -> 0 | C42: =IF('Items sous domaines Maths '!H46=1,'Items sous domaines Maths '!C46,0) -> 0 | D42: =IF('Items sous domaines Maths '!H46=1,'Items sous domaines Maths '!D46,0) -> 0 | E42: =IF('Items sous domaines Maths '!H46=1,'Items sous domaines Maths '!E46,0) -> 0 | F42: =IF('Items sous domaines Maths '!H46=1,'Items sous domaines Maths '!F46,0) -> 0
...

Sheet A1 CPI S2
A1: Objectifs d'apprentissage des Mathématiques
A2: Notions à maîtriser en CPI A1 S2 (+onglet A1 CPI S1)
A3: ='A1 CPI S1'!A3 -> EE du DS | B3: ='A1 CPI S1'!B3 -> Domaine | C3: ='A1 CPI S1'!C3 -> Discipline | D3: ='A1 CPI S1'!D3 -> Chapitres | E3: ='A1 CPI S1'!E3 -> Thèmes | F3: ='A1 CPI S1'!F3 -> Détail des chapitres | G3: Utilisation
A4: Algèbre : Nombres complexes, arithmétique | B4: =IF('Items sous domaines Maths '!H8=2,'Items sous domaines Maths '!B8,0) -> 0 | C4: =IF('Items sous domaines Maths '!H8=2,'Items sous domaines Maths '!C8) -> FALSE | D4: =IF('Items sous domaines Maths '!H8=2,'Items sous domaines Maths '!D8,0) -> 0 | E4: =IF('Items sous domaines Maths '!H8=2,'Items sous domaines Maths '!E8,0) -> 0 | F4: =IF('Items sous domaines Maths '!H8=2,'Items sous domaines Maths '!F8,0) -> 0 | G4: =IF('Items sous domaines Maths '!H8=2,'Items sous domaines Maths '!G8,0) -> 0
B5: =IF('Items sous domaines Maths '!H9=2,'Items sous domaines Maths '!B9,0) -> 0 | C5: =IF('Items sous domaines Maths '!H9=2,'Items sous domaines Maths '!C9) -> FALSE | D5: =IF('Items sous domaines Maths '!H9=2,'Items sous domaines Maths '!D9,0) -> 0 | E5: =IF('Items sous domaines Maths '!H9=2,'Items sous domaines Maths '!E9,0) -> 0 | F5: =IF('Items sous domaines Maths '!H9=2,'Items sous domaines Maths '!F9,0) -> 0 | G5: =IF('Items sous domaines Maths '!H9=2,'Items sous domaines Maths '!G9,0) -> 0
B6: =IF('Items sous domaines Maths '!H10=2,'Items sous domaines Maths '!B10,0) -> 0 | C6: =IF('Items sous domaines Maths '!H10=2,'Items sous domaines Maths '!C10) -> FALSE | D6: =IF('Items sous domaines Maths '!H10=2,'Items sous domaines Maths '!D10,0) -> 0 | E6: =IF('Items sous domaines Maths '!H10=2,'Items sous domaines Maths '!E10,0) -> 0 | F6: =IF('Items sous domaines Maths '!H10=2,'Items sous domaines Maths '!F10,0) -> 0 | G6: =IF('Items sous domaines Maths '!H10=2,'Items sous domaines Maths '!G10,0) -> 0
A7: Algèbre : arithmétique | B7: =IF('Items sous domaines Maths '!H11=2,'Items sous domaines Maths '!B11,0) -> 0 | C7: =IF('Items sous domaines Maths '!H11=2,'Items sous domaines Maths '!C11) -> FALSE | D7: =IF('Items sous domaines Maths '!H11=2,'Items sous domaines Maths '!D11,0) -> 0 | E7: =IF('Items sous domaines Maths '!H11=2,'Items sous domaines Maths '!E11,0) -> 0 | F7: =IF('Items sous domaines Maths '!H11=2,'Items sous domaines Maths '!F11,0) -> 0 | G7: ETS | H7: https://uel.unisciel.fr/mathematiques/arithmetique/arithmetique/co/arithmetique.html | I7: lien1
B8: =IF('Items sous domaines Maths '!H12=2,'Items sous domaines Maths '!B12,0) -> 0 | C8: =IF('Items sous domaines Maths '!H12=2,'Items sous domaines Maths '!C12) -> FALSE | D8: =IF('Items sous domaines Maths '!H12=2,'Items sous domaines Maths '!D12,0) -> 0 | E8: =IF('Items sous domaines Maths '!H12=2,'Items sous domaines Maths '!E12,0) -> 0 | F8: =IF('Items sous domaines Maths '!H12=2,'Items sous domaines Maths '!F12,0) -> 0 | I8: lien2
B9: =IF('Items sous domaines Maths '!H13=2,'Items sous domaines Maths '!B13,0) -> 0 | C9: =IF('Items sous domaines Maths '!H13=2,'Items sous domaines Maths '!C13) -> FALSE | D9: =IF('Items sous domaines Maths '!H13=2,'Items sous domaines Maths '!D13,0) -> 0 | E9: =IF('Items sous domaines Maths '!H13=2,'Items sous domaines Maths '!E13,0) -> 0 | F9: =IF('Items sous domaines Maths '!H13=2,'Items sous domaines Maths '!F13,0) -> 0 | I9: lien 3
B10: =IF('Items sous domaines Maths '!H14=2,'Items sous domaines Maths '!B14,0) -> 0 | C10: =IF('Items sous domaines Maths '!H14=2,'Items sous domaines Maths '!C14) -> FALSE | D10: =IF('Items sous domaines Maths '!H14=2,'Items sous domaines Maths '!D14,0) -> 0 | E10: =IF('Items sous domaines Maths '!H14=2,'Items sous domaines Maths '!E14,0) -> 0 | F10: =IF('Items sous domaines Maths '!H14=2,'Items sous domaines Maths '!F14,0) -> 0
B11: =IF('Items sous domaines Maths '!H15=2,'Items sous domaines Maths '!B15,0) -> 0 | C11: =IF('Items sous domaines Maths '!H15=2,'Items sous domaines Maths '!C15) -> FALSE | D11: =IF('Items sous domaines Maths '!H15=2,'Items sous domaines Maths '!D15,0) -> 0 | E11: =IF('Items sous domaines Maths '!H15=2,'Items sous domaines Maths '!E15,0) -> 0 | F11: =IF('Items sous domaines Maths '!H15=2,'Items sous domaines Maths '!F15,0) -> 0 | G11: =IF('Items sous domaines Maths '!H15=2,'Items sous domaines Maths '!G15,0) -> 0
B12: =IF('Items sous domaines Maths '!H16=2,'Items sous domaines Maths '!B16,0) -> 0 | C12: =IF('Items sous domaines Maths '!H16=2,'Items sous domaines Maths '!C16) -> FALSE | D12: =IF('Items sous domaines Maths '!H16=2,'Items sous domaines Maths '!D16,0) -> 0 | E12: =IF('Items sous domaines Maths '!H16=2,'Items sous domaines Maths '!E16,0) -> 0 | F12: =IF('Items sous domaines Maths '!H16=2,'Items sous domaines Maths '!F16,0) -> 0 | G12: =IF('Items sous domaines Maths '!H16=2,'Items sous domaines Maths '!G16,0) -> 0
B13: =IF('Items sous domaines Maths '!H17=2,'Items sous domaines Maths '!B17,0) -> 0 | C13: =IF('Items sous domaines Maths '!H17=2,'Items sous domaines Maths '!C17) -> FALSE | D13: =IF('Items sous domaines Maths '!H17=2,'Items sous domaines Maths '!D17,0) -> 0 | E13: =IF('Items sous domaines Maths '!H17=2,'Items sous domaines Maths '!E17,0) -> 0 | F13: =IF('Items sous domaines Maths '!H17=2,'Items sous domaines Maths '!F17,0) -> 0 | G13: =IF('Items sous domaines Maths '!H17=2,'Items sous domaines Maths '!G17,0) -> 0
B14: =IF('Items sous domaines Maths '!H18=2,'Items sous domaines Maths '!B18,0) -> 0 | C14: =IF('Items sous domaines Maths '!H18=2,'Items sous domaines Maths '!C18) -> FALSE | D14: =IF('Items sous domaines Maths '!H18=2,'Items sous domaines Maths '!D18,0) -> 0 | E14: =IF('Items sous domaines Maths '!H18=2,'Items sous domaines Maths '!E18,0) -> 0 | F14: =IF('Items sous domaines Maths '!H18=2,'Items sous domaines Maths '!F18,0) -> 0 | G14: =IF('Items sous domaines Maths '!H18=2,'Items sous domaines Maths '!G18,0) -> 0
B15: =IF('Items sous domaines Maths '!H19=2,'Items sous domaines Maths '!B19,0) -> 0 | C15: =IF('Items sous domaines Maths '!H19=2,'Items sous domaines Maths '!C19) -> FALSE | D15: =IF('Items sous domaines Maths '!H19=2,'Items sous domaines Maths '!D19,0) -> 0 | E15: =IF('Items sous domaines Maths '!H19=2,'Items sous domaines Maths '!E19,0) -> 0 | F15: =IF('Items sous domaines Maths '!H19=2,'Items sous domaines Maths '!F19,0) -> 0 | G15: =IF('Items sous domaines Maths '!H19=2,'Items sous domaines Maths '!G19,0) -> 0
B16: =IF('Items sous domaines Maths '!H20=2,'Items sous domaines Maths '!B20,0) -> 0 | C16: =IF('Items sous domaines Maths '!H20=2,'Items sous domaines Maths '!C20) -> FALSE | D16: =IF('Items sous domaines Maths '!H20=2,'Items sous domaines Maths '!D20,0) -> 0 | E16: =IF('Items sous domaines Maths '!H20=2,'Items sous domaines Maths '!E20,0) -> 0 | F16: =IF('Items sous domaines Maths '!H20=2,'Items sous domaines Maths '!F20,0) -> 0 | G16: =IF('Items sous domaines Maths '!H20=2,'Items sous domaines Maths '!G20,0) -> 0
B17: =IF('Items sous domaines Maths '!H21=2,'Items sous domaines Maths '!B21,0) -> 0 | C17: =IF('Items sous domaines Maths '!H21=2,'Items sous domaines Maths '!C21) -> FALSE | D17: =IF('Items sous domaines Maths '!H21=2,'Items sous domaines Maths '!D21,0) -> 0 | E17: =IF('Items sous domaines Maths '!H21=2,'Items sous domaines Maths '!E21,0) -> 0 | F17: =IF('Items sous domaines Maths '!H21=2,'Items sous domaines Maths '!F21,0) -> 0 | G17: =IF('Items sous domaines Maths '!H21=2,'Items sous domaines Maths '!G21,0) -> 0
B18: =IF('Items sous domaines Maths '!H22=2,'Items sous domaines Maths '!B22,0) -> 0 | C18: =IF('Items sous domaines Maths '!H22=2,'Items sous domaines Maths '!C22) -> FALSE | D18: =IF('Items sous domaines Maths '!H22=2,'Items sous domaines Maths '!D22,0) -> 0 | E18: =IF('Items sous domaines Maths '!H22=2,'Items sous domaines Maths '!E22,0) -> 0 | F18: =IF('Items sous domaines Maths '!H22=2,'Items sous domaines Maths '!F22,0) -> 0 | G18: =IF('Items sous domaines Maths '!H22=2,'Items sous domaines Maths '!G22,0) -> 0
B19: =IF('Items sous domaines Maths '!H23=2,'Items sous domaines Maths '!B23,0) -> 0 | C19: =IF('Items sous domaines Maths '!H23=2,'Items sous domaines Maths '!C23) -> FALSE | D19: =IF('Items sous domaines Maths '!H23=2,'Items sous domaines Maths '!D23,0) -> 0 | E19: =IF('Items sous domaines Maths '!H23=2,'Items sous domaines Maths '!E23,0) -> 0 | F19: =IF('Items sous domaines Maths '!H23=2,'Items sous domaines Maths '!F23,0) -> 0 | G19: =IF('Items sous domaines Maths '!H23=2,'Items sous domaines Maths '!G23,0) -> 0
B20: =IF('Items sous domaines Maths '!H24=2,'Items sous domaines Maths '!B24,0) -> 0 | C20: =IF('Items sous domaines Maths '!H24=2,'Items sous domaines Maths '!C24) -> FALSE | D20: =IF('Items sous domaines Maths '!H24=2,'Items sous domaines Maths '!D24,0) -> 0 | E20: =IF('Items sous domaines Maths '!H24=2,'Items sous domaines Maths '!E24,0) -> 0 | F20: =IF('Items sous domaines Maths '!H24=2,'Items sous domaines Maths '!F24,0) -> 0 | G20: =IF('Items sous domaines Maths '!H24=2,'Items sous domaines Maths '!G24,0) -> 0
B21: =IF('Items sous domaines Maths '!H25=2,'Items sous domaines Maths '!B25,0) -> 0 | C21: =IF('Items sous domaines Maths '!H25=2,'Items sous domaines Maths '!C25) -> FALSE | D21: =IF('Items sous domaines Maths '!H25=2,'Items sous domaines Maths '!D25,0) -> 0 | E21: =IF('Items sous domaines Maths '!H25=2,'Items sous domaines Maths '!E25,0) -> 0 | F21: =IF('Items sous domaines Maths '!H25=2,'Items sous domaines Maths '!F25,0) -> 0 | G21: =IF('Items sous domaines Maths '!H25=2,'Items sous domaines Maths '!G25,0) -> 0
B22: =IF('Items sous domaines Maths '!H26=2,'Items sous domaines Maths '!B26,0) -> 0 | C22: =IF('Items sous domaines Maths '!H26=2,'Items sous domaines Maths '!C26) -> FALSE | D22: =IF('Items sous domaines Maths '!H26=2,'Items sous domaines Maths '!D26,0) -> 0 | E22: =IF('Items sous domaines Maths '!H26=2,'Items sous domaines Maths '!E26,0) -> 0 | F22: =IF('Items sous domaines Maths '!H26=2,'Items sous domaines Maths '!F26,0) -> 0 | G22: =IF('Items sous domaines Maths '!H26=2,'Items sous domaines Maths '!G26,0) -> 0
... B25: =IF('Items sous domaines Maths '!H29=2,'Items sous domaines Maths '!B29,0) -> 0 | C25: =IF('Items sous domaines Maths '!H29=2,'Items sous domaines Maths '!C29) -> FALSE | D25: =IF('Items sous domaines Maths '!H29=2,'Items sous domaines Maths '!D29,0) -> 0 | E25: =IF('Items sous domaines Maths '!H29=2,'Items sous domaines Maths '!E29,0) -> 0 | F25: =IF('Items sous domaines Maths '!H29=2,'Items sous domaines Maths '!F29,0) -> 0 | G25: =IF('Items sous domaines Maths '!H29=2,'Items sous domaines Maths '!G29,0) -> 0
A26: Théorie des ensembles | B26: =IF('Items sous domaines Maths '!H30=2,'Items sous domaines Maths '!B30,0) -> 0 | C26: =IF('Items sous domaines Maths '!H30=2,'Items sous domaines Maths '!C30) -> FALSE | D26: =IF('Items sous domaines Maths '!H30=2,'Items sous domaines Maths '!D30,0) -> 0 | E26: =IF('Items sous domaines Maths '!H30=2,'Items sous domaines Maths '!E30,0) -> 0 | F26: =IF('Items sous domaines Maths '!H30=2,'Items sous domaines Maths '!F30,0) -> 0 | G26: Projet BDD
B27: =IF('Items sous domaines Maths '!H31=2,'Items sous domaines Maths '!B31,0) -> 0 | C27: =IF('Items sous domaines Maths '!H31=2,'Items sous domaines Maths '!C31) -> FALSE | D27: =IF('Items sous domaines Maths '!H31=2,'Items sous domaines Maths '!D31,0) -> 0 | E27: =IF('Items sous domaines Maths '!H31=2,'Items sous domaines Maths '!E31,0) -> 0 | F27: =IF('Items sous domaines Maths '!H31=2,'Items sous domaines Maths '!F31,0) -> 0
B28: =IF('Items sous domaines Maths '!H32=2,'Items sous domaines Maths '!B32,0) -> 0 | C28: =IF('Items sous domaines Maths '!H32=2,'Items sous domaines Maths '!C32) -> FALSE | D28: =IF('Items sous domaines Maths '!H32=2,'Items sous domaines Maths '!D32,0) -> 0 | E28: =IF('Items sous domaines Maths '!H32=2,'Items sous domaines Maths '!E32,0) -> 0 | F28: =IF('Items sous domaines Maths '!H32=2,'Items sous domaines Maths '!F32,0) -> 0 | G28: =IF('Items sous domaines Maths '!H32=2,'Items sous domaines Maths '!G32,0) -> 0
B29: =IF('Items sous domaines Maths '!H33=2,'Items sous domaines Maths '!B33,0) -> 0 | C29: =IF('Items sous domaines Maths '!H33=2,'Items sous domaines Maths '!C33) -> FALSE | D29: =IF('Items sous domaines Maths '!H33=2,'Items sous domaines Maths '!D33,0) -> 0 | E29: =IF('Items sous domaines Maths '!H33=2,'Items sous domaines Maths '!E33,0) -> 0 | F29: =IF('Items sous domaines Maths '!H33=2,'Items sous domaines Maths '!F33,0) -> 0 | G29: =IF('Items sous domaines Maths '!H33=2,'Items sous domaines Maths '!G33,0) -> 0
B30: =IF('Items sous domaines Maths '!H34=2,'Items sous domaines Maths '!B34,0) -> 0 | C30: =IF('Items sous domaines Maths '!H34=2,'Items sous domaines Maths '!C34) -> FALSE | D30: =IF('Items sous domaines Maths '!H34=2,'Items sous domaines Maths '!D34,0) -> 0 | E30: =IF('Items sous domaines Maths '!H34=2,'Items sous domaines Maths '!E34,0) -> 0 | F30: =IF('Items sous domaines Maths '!H34=2,'Items sous domaines Maths '!F34,0) -> 0 | G30: =IF('Items sous domaines Maths '!H34=2,'Items sous domaines Maths '!G34,0) -> 0
B31: =IF('Items sous domaines Maths '!H35=2,'Items sous domaines Maths '!B35,0) -> 0 | C31: =IF('Items sous domaines Maths '!H35=2,'Items sous domaines Maths '!C35) -> FALSE | D31: =IF('Items sous domaines Maths '!H35=2,'Items sous domaines Maths '!D35,0) -> 0 | E31: =IF('Items sous domaines Maths '!H35=2,'Items sous domaines Maths '!E35,0) -> 0 | F31: =IF('Items sous domaines Maths '!H35=2,'Items sous domaines Maths '!F35,0) -> 0 | G31: =IF('Items sous domaines Maths '!H35=2,'Items sous domaines Maths '!G35,0) -> 0
B32: =IF('Items sous domaines Maths '!H36=2,'Items sous domaines Maths '!B36,0) -> 0 | C32: =IF('Items sous domaines Maths '!H36=2,'Items sous domaines Maths '!C36) -> FALSE | D32: =IF('Items sous domaines Maths '!H36=2,'Items sous domaines Maths '!D36,0) -> 0 | E32: =IF('Items sous domaines Maths '!H36=2,'Items sous domaines Maths '!E36,0) -> 0 | F32: =IF('Items sous domaines Maths '!H36=2,'Items sous domaines Maths '!F36,0) -> 0 | G32: =IF('Items sous domaines Maths '!H36=2,'Items sous domaines Maths '!G36,0) -> 0
B33: =IF('Items sous domaines Maths '!H37=2,'Items sous domaines Maths '!B37,0) -> 0 | C33: =IF('Items sous domaines Maths '!H37=2,'Items sous domaines Maths '!C37) -> FALSE | D33: =IF('Items sous domaines Maths '!H37=2,'Items sous domaines Maths '!D37,0) -> 0 | E33: =IF('Items sous domaines Maths '!H37=2,'Items sous domaines Maths '!E37,0) -> 0 | F33: =IF('Items sous domaines Maths '!H37=2,'Items sous domaines Maths '!F37,0) -> 0 | G33: =IF('Items sous domaines Maths '!H37=2,'Items sous domaines Maths '!G37,0) -> 0
B34: =IF('Items sous domaines Maths '!H38=2,'Items sous domaines Maths '!B38,0) -> 0 | C34: =IF('Items sous domaines Maths '!H38=2,'Items sous domaines Maths '!C38) -> FALSE | D34: =IF('Items sous domaines Maths '!H38=2,'Items sous domaines Maths '!D38,0) -> 0 | E34: =IF('Items sous domaines Maths '!H38=2,'Items sous domaines Maths '!E38,0) -> 0 | F34: =IF('Items sous domaines Maths '!H38=2,'Items sous domaines Maths '!F38,0) -> 0 | G34: =IF('Items sous domaines Maths '!H38=2,'Items sous domaines Maths '!G38,0) -> 0
B35: =IF('Items sous domaines Maths '!H39=2,'Items sous domaines Maths '!B39,0) -> 0 | C35: =IF('Items sous domaines Maths '!H39=2,'Items sous domaines Maths '!C39) -> FALSE | D35: =IF('Items sous domaines Maths '!H39=2,'Items sous domaines Maths '!D39,0) -> 0 | E35: =IF('Items sous domaines Maths '!H39=2,'Items sous domaines Maths '!E39,0) -> 0 | F35: =IF('Items sous domaines Maths '!H39=2,'Items sous domaines Maths '!F39,0) -> 0 | G35: =IF('Items sous domaines Maths '!H39=2,'Items sous domaines Maths '!G39,0) -> 0
A36: Algèbre : Nombres complexes | B36: =IF('Items sous domaines Maths '!H40=2,'Items sous domaines Maths '!B40,0) -> Algèbre | C36: =IF('Items sous domaines Maths '!H40=2,'Items sous domaines Maths '!C40) -> Les nombres complexes | D36: =IF('Items sous domaines Maths '!H40=2,'Items sous domaines Maths '!D40,0) -> Définition et écriture algébrique des nombres complexes | E36: =IF('Items sous domaines Maths '!H40=2,'Items sous domaines Maths '!E40,0) -> Définition | F36: =IF('Items sous domaines Maths '!H40=2,'Items sous domaines Maths '!F40,0) -> Connaître l'écriture algébrique, la partie réelle et imaginaire d'un nombre complexe | G36: =IF('Items sous domaines Maths '!H40=2,'Items sous domaines Maths '!G40,0) -> 0
B37: =IF('Items sous domaines Maths '!H41=2,'Items sous domaines Maths '!B41,0) -> Algèbre | C37: =IF('Items sous domaines Maths '!H41=2,'Items sous domaines Maths '!C41) -> Les nombres complexes | D37: =IF('Items sous domaines Maths '!H41=2,'Items sous domaines Maths '!D41,0) -> 0 | E37: =IF('Items sous domaines Maths '!H41=2,'Items sous domaines Maths '!E41,0) -> 0 | F37: =IF('Items sous domaines Maths '!H41=2,'Items sous domaines Maths '!F41,0) -> Savoir faire des opérations sur les nombres complexes. | G37: =IF('Items sous domaines Maths '!H41=2,'Items sous domaines Maths '!G41,0) -> 0
B38: =IF('Items sous domaines Maths '!H42=2,'Items sous domaines Maths '!B42,0) -> Algèbre | C38: =IF('Items sous domaines Maths '!H42=2,'Items sous domaines Maths '!C42) -> Les nombres complexes | D38: =IF('Items sous domaines Maths '!H42=2,'Items sous domaines Maths '!D42,0) -> 0 | E38: =IF('Items sous domaines Maths '!H42=2,'Items sous domaines Maths '!E42,0) -> 0 | F38: =IF('Items sous domaines Maths '!H42=2,'Items sous domaines Maths '!F42,0) -> Connaître et savoir calculer le conjugué d'un nombre complexe. Connaître les propriétés du conjugué et son utilité dans l'écriture des fractions complexes sous forme algébrique. | G38: =IF('Items sous domaines Maths '!H42=2,'Items sous domaines Maths '!G42,0) -> 0
B39: =IF('Items sous domaines Maths '!H43=2,'Items sous domaines Maths '!B43,0) -> Algèbre | C39: =IF('Items sous domaines Maths '!H43=2,'Items sous domaines Maths '!C43) -> Les nombres complexes | D39: =IF('Items sous domaines Maths '!H43=2,'Items sous domaines Maths '!D43,0) -> 0 | E39: =IF('Items sous domaines Maths '!H43=2,'Items sous domaines Maths '!E43,0) -> 0 | F39: =IF('Items sous domaines Maths '!H43=2,'Items sous domaines Maths '!F43,0) -> Savoir associer un point du plan à un nombre complexe, affixe d’un point du plan, affixe d’un vecteur du plan (dentifier C au plan usuel muni d’un repère orthonormé direct) | G39: =IF('Items sous domaines Maths '!H43=2,'Items sous domaines Maths '!G43,0) -> 0
B40: =IF('Items sous domaines Maths '!H44=2,'Items sous domaines Maths '!B44,0) -> Algèbre | C40: =IF('Items sous domaines Maths '!H44=2,'Items sous domaines Maths '!C44) -> Les nombres complexes | D40: =IF('Items sous domaines Maths '!H44=2,'Items sous domaines Maths '!D44,0) -> 0 | E40: =IF('Items sous domaines Maths '!H44=2,'Items sous domaines Maths '!E44,0) -> Module d’un nombre complexe | F40: =IF('Items sous domaines Maths '!H44=2,'Items sous domaines Maths '!F44,0) -> Savoir calculer un module d'un nombre complexe. | G40: =IF('Items sous domaines Maths '!H44=2,'Items sous domaines Maths '!G44,0) -> 0
B41: =IF('Items sous domaines Maths '!H45=2,'Items sous domaines Maths '!B45,0) -> Algèbre | C41: =IF('Items sous domaines Maths '!H45=2,'Items sous domaines Maths '!C45) -> Les nombres complexes | D41: =IF('Items sous domaines Maths '!H45=2,'Items sous domaines Maths '!D45,0) -> 0 | E41: =IF('Items sous domaines Maths '!H45=2,'Items sous domaines Maths '!E45,0) -> 0 | F41: =IF('Items sous domaines Maths '!H45=2,'Items sous domaines Maths '!F45,0) -> Connaître l'interprétation géométrique d'un module et repérer les images des affixes de même module. | G41: =IF('Items sous domaines Maths '!H45=2,'Items sous domaines Maths '!G45,0) -> 0
B42: =IF('Items sous domaines Maths '!H46=2,'Items sous domaines Maths '!B46,0) -> Algèbre | C42: =IF('Items sous domaines Maths '!H46=2,'Items sous domaines Maths '!C46) -> Les nombres complexes | D42: =IF('Items sous domaines Maths '!H46=2,'Items sous domaines Maths '!D46,0) -> 0 | E42: =IF('Items sous domaines Maths '!H46=2,'Items sous domaines Maths '!E46,0) -> 0 | F42: =IF('Items sous domaines Maths '!H46=2,'Items sous domaines Maths '!F46,0) -> Savoir calculer le module d’un produit, d’un quotient. | G42: =IF('Items sous domaines Maths '!H46=2,'Items sous domaines Maths '!G46,0) -> 0
...

Sheet A2 CPI S3 
A1: Objectifs d'apprentissage des Mathématiques
A2: Notions à maîtriser en A2 (en révisant le socle A1)
A3: ='A1 CPI S1'!A3 -> EE du DS | B3: ='A1 CPI S1'!B3 -> Domaine | C3: ='A1 CPI S1'!C3 -> Discipline | D3: ='A1 CPI S1'!D3 -> Chapitres | E3: ='A1 CPI S1'!E3 -> Thèmes | F3: ='A1 CPI S1'!F3 -> Détail des chapitres | G3: ='A1 CPI S1'!G3 -> Utilisation
